Workbook
Name AllData: Report!$A$7:$AB$140

Sheet Data
A1: CompanyName | B1: United Civil Construction Limited
A2: RunDate | B2: 45975.863
A3: TimeZone | B3: Pacific/Auckland
A4: DistanceUnit | B4: km
A5: SendReport | B5: TRUE
A6: LastModifiedUser | B6: System
A7: Language | B7: en
A8: DeviceName | B8: DeviceId | C8: DeviceGroup | D8: DeviceParentGroup | E8: DeviceGroup|Company Group | F8: CurrentDriver.UserFirstName | G8: CurrentDriver.UserLastName | H8: CurrentDriver.UserName | I8: WorkTimeName | J8: DeviceDetailsDevicePlan | K8: DeviceDetailsDrivingState | L8: DeviceDetailsPrivacyMode | M8: DeviceDetailsCurrentExceptions | N8: DeviceDetailsLocation | O8: Location.ZoneZoneTypes | P8: Location.ZoneExternalReference | Q8: DeviceDetailsCurrentOdometer | R8: DeviceDetailsCurrentEngineHours | S8: DeviceActiveFrom | T8: DeviceActiveTo | U8: DeviceDeviceType | V8: DeviceProductId | W8: DeviceMajor | X8: DeviceMinor | Y8: DeviceSerialNumber | Z8: DeviceLicensePlate | AA8: DeviceLicenseState | AB8: AutoVehicleManagement | AC8: HosSettings | AD8: DeviceVIN | AE8: DeviceEngineVIN | AF8: DeviceTimeZoneId | AG8: DeviceComment | AH8: DeviceStatusLastTrip | AI8: DeviceStatusLastGpsRecord | AJ8: DeviceCommunicationStatusState | AK8: DeviceCommunicationStatusStateInfo | AL8: DeviceStatusAnalysisTroubleDownloadStatus | AM8: DeviceProgrammingImmobilizeArming | AN8: DeviceProgrammingSpeedingOn | AO8: DeviceProgrammingSpeedingOff | AP8: DeviceProgrammingIdleMinutes | AQ8: DeviceProgrammingRpmValue | AR8: DeviceProgrammingHarshBrakeWarning | AS8: DeviceProgrammingOdometerOffset | AT8: DeviceProgrammingEngineHourOffset | AU8: DeviceDetailsMake | AV8: DeviceDetailsModel | AW8: DeviceDetailsYear | AX8: DeviceDetailsExtra
A9: 1 | B9: b2F2 | C9: Vehicle, EV/Other Management | D9: Company Group>Asset Information>Asset Type>Vehicle, Company Group>EV/Other Management | E9: EV/Other Management, Vehicle | I9: Standard Hours | J9: Terminate Mode,UI | L9: FALSE | Q9: 0 | R9: 0 | S9: 45948.893 | T9: 54789.542 | U9: Version 9 | V9: 120 | W9: 0 | X9: 0 | Y9: G9W1PJSDBFNV | AB9: FALSE | AC9: On | AE9: ? | AF9: UTC | AJ9: DeviceTerminated | AK9: The device Rate Plan has been terminated, and cannot be reactivated. Contact your fleet's Telematics Representative to order a new device. | AS9: 0 | AT9: 0 | AX9: VIN Error: CouldNotDecodeError;
A10: 103 | B10: b161 | C10: Digger, Excavator/Tradestaff, Machines, Trade Staff | D10: Company Group>Asset Information>Asset Type>Vehicle>Digger, Company Group>Excavator/Tradestaff, Company Group>Machines, Company Group>Trade Staff | E10: Digger, Excavator/Tradestaff, Machines, Trade Staff | I10: Standard Hours | J10: GO Mode,Garmin,HOS,Iridium,UI | K10: Stopped | L10: FALSE | M10: Channel Infrastructure | N10: Channel Infrastructure: 41 Mair Road, Marsden Point 0171, New Zealand | O10: Project | Q10: 283.65958 | R10: 348.29408 | S10: 45782.821 | T10: 54789.542 | U10: Version 9 | V10: 120 | W10: 42 | X10: 57 | Y10: G9JS3X5N41M7 | Z10: EUG563 | AB10: FALSE | AC10: On | AE10: @@@@@@@@@@@@@@@@@ | AF10: Pacific/Auckland | AG10: 14T Hitachi ZX140W-3 2009 | AH10: 45974.543 | AI10: 45975.849 | AL10: OK | AS10: 0 | AT10: 0 | AX10: VIN Error: CouldNotDecodeError;
A11: 1080 | B11: b2C5 | C11: Generator, Generator/Trade Staff, Trade Staff | D11: Company Group>Asset Information>Asset Type>Vehicle>Generator, Company Group>Generator/Trade Staff, Company Group>Trade Staff | E11: Generator, Generator/Trade Staff, Trade Staff | I11: Standard Hours | L11: FALSE | Q11: 0 | R11: 0 | S11: 45929.439 | T11: 54789.542 | U11: None | V11: -1 | AB11: FALSE | AC11: NotApplicable | AF11: UTC | AG11: P9 Fox | AS11: 0 | AT11: 0 | AX11: VIN Error: CouldNotDecodeError;
A12: 1081 | B12: b2C6 | C12: Generator, Generator/Trade Staff, Trade Staff | D12: Company Group>Asset Information>Asset Type>Vehicle>Generator, Company Group>Generator/Trade Staff, Company Group>Trade Staff | E12: Generator, Generator/Trade Staff, Trade Staff | I12: Standard Hours | L12: FALSE | Q12: 0 | R12: 521.54167 | S12: 45929.44 | T12: 54789.542 | U12: None | V12: -1 | AB12: FALSE | AC12: NotApplicable | AF12: UTC | AG12: P15 Fox | AS12: 0 | AT12: 0 | AX12: VIN Error: CouldNotDecodeError;
A13: 111 | B13: b176 | C13: Digger, Battery Electric Vehicle, Excavator/Tradestaff, Machines | D13: Company Group>Asset Information>Asset Type>Vehicle>Digger, Company Group>Asset Information>Powertrain and Fuel Type>Electric or Plug-In Hybrid>Battery Electric Vehicle, Company Group>Excavator/Tradestaff, Company Group>Machines | E13: Battery Electric Vehicle, Digger, Excavator/Tradestaff, Machines | F13: Archie | G13: Abellana | H13: archie.abellana | I13: Standard Hours | J13: GO Mode,Garmin,HOS,Iridium,UI | K13: Stopped | L13: FALSE | M13: Gillingham Road | N13: Gillingham Road: 75 Gillingham Road, Te Kamo, Whangārei 0112, New Zealand | O13: Project | Q13: 153.15073 | R13: 344.52307 | S13: 45842.406 | T13: 54789.542 | U13: Version 9 | V13: 120 | W13: 42 | X13: 57 | Y13: G9RHXM0XNPXP | AB13: FALSE | AC13: Off | AE13: @@@@@@@@@@@@@@@@@ | AF13: Pacific/Auckland | AG13: 13.5T Hitachi ZX135USLC-3 2012 | AH13: 45975.659 | AI13: 45975.848 | AL13: OK | AS13: 0 | AT13: 0 | AX13: VIN Error: CouldNotDecodeError;
A14: 1141 | B14: b2C7 | C14: Generator, Generator/Trade Staff, Trade Staff | D14: Company Group>Asset Information>Asset Type>Vehicle>Generator, Company Group>Generator/Trade Staff, Company Group>Trade Staff | E14: Generator, Generator/Trade Staff, Trade Staff | I14: Standard Hours | L14: FALSE | Q14: 0 | R14: 0 | S14: 45929.44 | T14: 54789.542 | U14: None | V14: -1 | AB14: FALSE | AC14: NotApplicable | AF14: UTC | AS14: 0 | AT14: 0 | AX14: VIN Error: CouldNotDecodeError;
A15: 122 | B15: b164 | C15: Digger, Excavator/Tradestaff, Machines, Trade Staff | D15: Company Group>Asset Information>Asset Type>Vehicle>Digger, Company Group>Excavator/Tradestaff, Company Group>Machines, Company Group>Trade Staff | E15: Digger, Excavator/Tradestaff, Machines, Trade Staff | I15: Standard Hours | J15: GO Mode,Garmin,HOS,Iridium,UI | K15: Stopped | L15: FALSE | M15: Kaitaia Wastewater | N15: Kaitaia Wastewater: 10 Puckey Avenue, Kaitaia 0410, New Zealand | O15: Project | Q15: 398.496 | R15: 277.74583 | S15: 45782.825 | T15: 54789.542 | U15: Version 9 | V15: 120 | W15: 42 | X15: 57 | Y15: G9071KVMB37P | AB15: FALSE | AC15: On | AE15: ????????????????? | AF15: Pacific/Auckland | AG15: 5.5T Hitachi ZX55U-5 2014 | AH15: 45967.487 | AI15: 45975.469 | AL15: OK | AS15: 0 | AT15: 0 | AX15: VIN Error: CouldNotDecodeError;
A16: 123 | B16: b16A | C16: Digger, Excavator/Tradestaff, Machines, Trade Staff | D16: Company Group>Asset Information>Asset Type>Vehicle>Digger, Company Group>Excavator/Tradestaff, Company Group>Machines, Company Group>Trade Staff | E16: Digger, Excavator/Tradestaff, Machines, Trade Staff | I16: Standard Hours | J16: GO Mode,Garmin,HOS,Iridium,UI | K16: Stopped | L16: FALSE | M16: Channel Infrastructure | N16: Channel Infrastructure: 41 Mair Road, Marsden Point 0171, New Zealand | O16: Project | Q16: 41.567631 | R16: 125.61197 | S16: 45782.835 | T16: 54789.542 | U16: Version 9 | V16: 120 | W16: 42 | X16: 57 | Y16: G9F8JM3179FZ | AB16: FALSE | AC16: Off | AE16: @@@@@@@@@@@@@@@@@ | AF16: Pacific/Auckland | AG16: 1.7T Hitachi ZX17U-2 2014 | AH16: 45974.547 | AI16: 45975.842 | AL16: OK | AS16: 0 | AT16: 0 | AX16: VIN Error: CouldNotDecodeError;
A17: 124 | B17: b166 | C17: Digger, Diesel, Excavator/Tradestaff, Machines, Trade Staff | D17: Company Group>Asset Information>Asset Type>Vehicle>Digger, Company Group>Asset Information>Powertrain and Fuel Type>Internal Combustion Engine>Diesel, Company Group>Excavator/Tradestaff, Company Group>Machines, Company Group>Trade Staff | E17: Diesel, Digger, Excavator/Tradestaff, Machines, Trade Staff | I17: Standard Hours | J17: GO Mode,Garmin,HOS,Iridium,UI | K17: Stopped | L17: FALSE | M17: Morningside | N17: Morningside: 65 Morningside Rd, Northland Region 0110, New Zealand | O17: Project | Q17: 229.87764 | R17: 388.45 | S17: 45782.834 | T17: 54789.542 | U17: Version 9 | V17: 120 | W17: 42 | X17: 57 | Y17: G9EKK0KRFU3Y | AB17: FALSE | AC17: Off | AE17: jjjjjjjjjjjjjjjjj | AF17: Pacific/Auckland | AG17: 23.5T Hyundai R235 LCR-9 2014 | AH17: 45975.821 | AI17: 45975.844 | AL17: OK | AS17: 0 | AT17: 0 | AX17: VIN Error: CouldNotDecodeError;
A18: 128 | B18: b170 | C18: Digger, Diesel, Excavator/Tradestaff, Machines, Trade Staff | D18: Company Group>Asset Information>Asset Type>Vehicle>Digger, Company Group>Asset Information>Powertrain and Fuel Type>Internal Combustion Engine>Diesel, Company Group>Excavator/Tradestaff, Company Group>Machines, Company Group>Trade Staff | E18: Diesel, Digger, Excavator/Tradestaff, Machines, Trade Staff | I18: Standard Hours | J18: GO Mode,Garmin,HOS,Iridium,UI | K18: Stopped | L18: FALSE | M18: Morningside | N18: Morningside: 65 Morningside Rd, Northland Region 0110, New Zealand | O18: Project | Q18: 265.51221 | R18: 322.36667 | S18: 45782.834 | T18: 54789.542 | U18: Version 9 | V18: 120 | W18: 42 | X18: 57 | Y18: G9USRCKV6BVV | AB18: FALSE | AC18: Off | AE18: jjjjjjjjjjjjjjjjj | AF18: Pacific/Auckland | AG18: 23.5T Hyundai R235LCR-9 2016 | AH18: 45975.742 | AI18: 45975.847 | AL18: OK | AS18: 0 | AT18: 0 | AX18: VIN Error: CouldNotDecodeError;
A19: 129 | B19: b160 | C19: Digger, Excavator/Tradestaff, Machines, Trade Staff | D19: Company Group>Asset Information>Asset Type>Vehicle>Digger, Company Group>Excavator/Tradestaff, Company Group>Machines, Company Group>Trade Staff | E19: Digger, Excavator/Tradestaff, Machines, Trade Staff | I19: Standard Hours | J19: GO Mode,Garmin,HOS,Iridium,UI | K19: Stopped | L19: FALSE | M19: Kaitaia Wastewater | N19: Kaitaia Wastewater: 1 Bonnetts Road, Kaitaia 0410, New Zealand | O19: Project | Q19: 244.47006 | R19: 6.0732569 | S19: 45782.834 | T19: 54789.542 | U19: Version 9 | V19: 120 | W19: 42 | X19: 57 | Y19: G940DTZJ0XM1 | AB19: FALSE | AC19: Off | AE19: @@@@@@@@@@@@@@@@@ | AF19: Pacific/Auckland | AG19: 1.7T Hyundai R17z-19A 2017 | AH19: 45975.334 | AI19: 45975.863 | AL19: OK | AS19: 0 | AT19: 0 | AX19: VIN Error: CouldNotDecodeError;
A20: 130 | B20: b16E | C20: Digger, Excavator/Tradestaff, Machines, Trade Staff | D20: Company Group>Asset Information>Asset Type>Vehicle>Digger, Company Group>Excavator/Tradestaff, Company Group>Machines, Company Group>Trade Staff | E20: Digger, Excavator/Tradestaff, Machines, Trade Staff | I20: Standard Hours | J20: GO Mode,Garmin,HOS,Iridium,UI | K20: Stopped | L20: FALSE | M20: Ngawha,Ngawha | N20: Ngawha: 73B Bannister Road, Ngawha Springs 0472, New Zealand | O20: Project | Q20: 549.59198 | R20: 88.830679 | S20: 45782.835 | T20: 54789.542 | U20: Version 9 | V20: 120 | W20: 42 | X20: 57 | Y20: G9K3YS8BXU3J | AB20: FALSE | AC20: Off | AE20: @@@@@@@@@@@@@@@@@ | AF20: Pacific/Auckland | AG20: 1.7T Hyundai R17z-19A 2017 | AH20: 45974.572 | AI20: 45975.856 | AL20: OK | AS20: 0 | AT20: 0 | AX20: VIN Error: CouldNotDecodeError;
A21: 1304 | B21: b2C8 | C21: Pump, Pump/Trade Staff, Trade Staff | D21: Company Group>Asset Information>Asset Type>Vehicle>Pump, Company Group>Pump/Trade Staff, Company Group>Trade Staff | E21: Pump, Pump/Trade Staff, Trade Staff | I21: Standard Hours | L21: FALSE | Q21: 0 | R21: 0 | S21: 45929.442 | T21: 54789.542 | U21: None | V21: -1 | AB21: FALSE | AC21: NotApplicable | AF21: UTC | AG21: Pump - Vacuum Prime Pumpset BA100K | AS21: 0 | AT21: 0 | AX21: VIN Error: CouldNotDecodeError;
A22: 132 | B22: b178 | C22: Digger, Excavator/Tradestaff, Machines, Trade Staff | D22: Company Group>Asset Information>Asset Type>Vehicle>Digger, Company Group>Excavator/Tradestaff, Company Group>Machines, Company Group>Trade Staff | E22: Digger, Excavator/Tradestaff, Machines, Trade Staff | F22: Kymani | G22: Paikea | H22: kymani.paikea | I22: Standard Hours | J22: GO Mode,Garmin,HOS,Iridium,UI | K22: Stopped | L22: FALSE | M22: Ruakaka Solar Farm Site 2 | N22: Ruakaka Solar Farm Site 2: 34 Mccathie Road, Ruakākā 0171, New Zealand | O22: Project | Q22: 132.82076 | R22: 208.99308 | S22: 45782.835 | T22: 54789.542 | U22: Version 9 | V22: 120 | W22: 42 | X22: 57 | Y22: G98ZPSY1BD3K | AB22: FALSE | AC22: Off | AE22: @@@@@@@@@@@@@@@@@ | AF22: Pacific/Auckland | AG22: 8T Hyundai R80CR-9 2018 | AH22: 45972.514 | AI22: 45975.517 | AL22: OK | AS22: 0 | AT22: 0 | AX22: VIN Error: CouldNotDecodeError;
A23: 133 | B23: b17B | C23: Digger, Diesel, Excavator/Tradestaff, Machines, Trade Staff | D23: Company Group>Asset Information>Asset Type>Vehicle>Digger, Company Group>Asset Information>Powertrain and Fuel Type>Internal Combustion Engine>Diesel, Company Group>Excavator/Tradestaff, Company Group>Machines, Company Group>Trade Staff | E23: Diesel, Digger, Excavator/Tradestaff, Machines, Trade Staff | I23: Standard Hours | J23: GO Mode,Garmin,HOS,Iridium,UI | K23: Stopped | L23: FALSE | M23: Kaitaia Wastewater | N23: Kaitaia Wastewater: 4 Bonnetts Road, Kaitaia 0410, New Zealand | O23: Project | Q23: 307.37079 | R23: 271.12686 | S23: 45782.835 | T23: 54789.542 | U23: Version 9 | V23: 120 | W23: 42 | X23: 57 | Y23: G9JN6AVZ9WNA | AB23: FALSE | AC23: Off | AE23: @@@@@@@@@@@@@@@@@ | AF23: Pacific/Auckland | AG23: 22.5T Hitachi ZX225 USLC-5 2018 | AH23: 45975.629 | AI23: 45975.86 | AL23: OK | AS23: 0 | AT23: 0 | AX23: VIN Error: CouldNotDecodeError;
A24: 134 | B24: b179 | C24: Digger, Excavator/Tradestaff, Machines, Trade Staff | D24: Company Group>Asset Information>Asset Type>Vehicle>Digger, Company Group>Excavator/Tradestaff, Company Group>Machines, Company Group>Trade Staff | E24: Digger, Excavator/Tradestaff, Machines, Trade Staff | I24: Standard Hours | J24: GO Mode,Garmin,HOS,Iridium,UI | K24: Stopped | L24: FALSE | M24: Kaikohe Work Area | N24: Kaikohe Work Area: 39 Bisset Road, Kaikohe 0405, New Zealand | O24: Project | Q24: 353.31464 | R24: 189.65722 | S24: 45782.836 | T24: 54789.542 | U24: Version 9 | V24: 120 | W24: 42 | X24: 57 | Y24: G9AXAZ5WJSNC | AB24: FALSE | AC24: Off | AE24: @@@@@@@@@@@@@@@@@ | AF24: Pacific/Auckland | AG24: 14.5T Hyundai R145CRD-9 2018 | AH24: 45975.646 | AI24: 45975.855 | AL24: OK | AS24: 0 | AT24: 0 | AX24: VIN Error: CouldNotDecodeError;
A25: 137 | B25: b173 | C25: Digger, Excavator/Tradestaff, Machines, Trade Staff | D25: Company Group>Asset Information>Asset Type>Vehicle>Digger, Company Group>Excavator/Tradestaff, Company Group>Machines, Company Group>Trade Staff | E25: Digger, Excavator/Tradestaff, Machines, Trade Staff | I25: Standard Hours | J25: GO Mode,Garmin,HOS,Iridium,UI | K25: Stopped | L25: FALSE | M25: Kaikohe | N25: Kaikohe: 91 Mangakahia Road, Kaikohe 0474, New Zealand | O25: Project | Q25: 361.92508 | R25: 110.25417 | S25: 45782.836 | T25: 54789.542 | U25: Version 9 | V25: 120 | W25: 42 | X25: 57 | Y25: G960M159TRJS | AB25: FALSE | AC25: Off | AE25: ????????????????? | AF25: Pacific/Auckland | AG25: 6T Hitachi ZX65USB-5A 2018 | AH25: 45975.463 | AI25: 45975.86 | AL25: OK | AS25: 0 | AT25: 0 | AX25: VIN Error: CouldNotDecodeError;
A26: 138 | B26: b16B | C26: Digger, Diesel, Excavator/Tradestaff, Machines, Trade Staff | D26: Company Group>Asset Information>Asset Type>Vehicle>Digger, Company Group>Asset Information>Powertrain and Fuel Type>Internal Combustion Engine>Diesel, Company Group>Excavator/Tradestaff, Company Group>Machines, Company Group>Trade Staff | E26: Diesel, Digger, Excavator/Tradestaff, Machines, Trade Staff | I26: Standard Hours | J26: GO Mode,Garmin,HOS,Iridium,UI | K26: Stopped | L26: FALSE | M26: Morningside | N26: Morningside: 60 Morningside Road, Morningside, Whangārei 0110, New Zealand | O26: Project | Q26: 218.2724 | R26: 189.65398 | S26: 45782.836 | T26: 54789.542 | U26: Version 9 | V26: 120 | W26: 42 | X26: 57 | Y26: G9ZT0W7U7AX9 | AB26: FALSE | AC26: Off | AE26: @@@@@@@@@@@@@@@@@ | AF26: Pacific/Auckland | AG26: 13.5T Hitachi ZX135US-5B 2019 | AH26: 45973.33 | AI26: 45975.853 | AL26: OK | AS26: 0 | AT26: 0 | AX26: VIN Error: CouldNotDecodeError;
A27: 139 | B27: b17A | C27: Digger, Diesel, Excavator/Tradestaff, Machines, Trade Staff | D27: Company Group>Asset Information>Asset Type>Vehicle>Digger, Company Group>Asset Information>Powertrain and Fuel Type>Internal Combustion Engine>Diesel, Company Group>Excavator/Tradestaff, Company Group>Machines, Company Group>Trade Staff | E27: Diesel, Digger, Excavator/Tradestaff, Machines, Trade Staff | I27: Standard Hours | J27: GO Mode,Garmin,HOS,Iridium,UI | K27: Stopped | L27: FALSE | M27: Kaitaia Wastewater | N27: Kaitaia Wastewater: 5 Eden Terrace, Kaitaia 0410, New Zealand | O27: Project | Q27: 201.37395 | R27: 103.13083 | S27: 45782.837 | T27: 54789.542 | U27: Version 9 | V27: 120 | W27: 42 | X27: 57 | Y27: G9KESM7CCB7P | AB27: FALSE | AC27: Off | AE27: @@@@@@@@@@@@@@@@@ | AF27: Pacific/Auckland | AG27: 13.5T Hitachi ZX135US-5B 2022 | AH27: 45974.655 | AI27: 45975.844 | AL27: OK | AS27: 0 | AT27: 0 | AX27: VIN Error: CouldNotDecodeError;
A28: 140 | B28: b165 | C28: Digger, Excavator/Tradestaff, Machines, Trade Staff | D28: Company Group>Asset Information>Asset Type>Vehicle>Digger, Company Group>Excavator/Tradestaff, Company Group>Machines, Company Group>Trade Staff | E28: Digger, Excavator/Tradestaff, Machines, Trade Staff | I28: Standard Hours | J28: GO Mode,Garmin,HOS,Iridium,UI | K28: Stopped | L28: FALSE | M28: Channel Infrastructure | N28: Channel Infrastructure: Timber Trail, Northland Region, New Zealand | O28: Project | Q28: 10.799479 | R28: 52.547708 | S28: 45782.839 | T28: 54789.542 | U28: Version 9 | V28: 120 | W28: 42 | X28: 57 | Y28: G95WT8P1KVE4 | AB28: FALSE | AC28: Off | AE28: ? | AF28: Pacific/Auckland | AG28: 2.6T Hitachi ZX26U-5A 2022 | AH28: 45974.633 | AI28: 45975.5 | AL28: OK | AS28: 0 | AT28: 0 | AX28: VIN Error: CouldNotDecodeError;
A29: 141 | B29: b175 | C29: Digger, Excavator/Tradestaff, Machines, Trade Staff | D29: Company Group>Asset Information>Asset Type>Vehicle>Digger, Company Group>Excavator/Tradestaff, Company Group>Machines, Company Group>Trade Staff | E29: Digger, Excavator/Tradestaff, Machines, Trade Staff | F29: Paul | G29: Travers | H29: paul.travers | I29: Standard Hours | J29: GO Mode,Garmin,HOS,Iridium,UI | K29: Stopped | L29: FALSE | M29: Morningside | N29: Morningside: 80 Morningside Road, Morningside, Whangārei 0110, New Zealand | O29: Project | Q29: 1909.9972 | R29: 90.6 | S29: 45782.839 | T29: 54789.542 | U29: Version 9 | V29: 120 | W29: 42 | X29: 57 | Y29: G97JWZZS6MBT | AB29: FALSE | AC29: Off | AE29: ????????????????? | AF29: Pacific/Auckland | AG29: 6T Hitachi ZX65USB-5A 2022 | AH29: 45975.643 | AI29: 45975.858 | AL29: OK | AS29: 0 | AT29: 0 | AX29: VIN Error: CouldNotDecodeError;
A30: 142 | B30: b167 | C30: Digger, Excavator/Tradestaff, Machines, Trade Staff | D30: Company Group>Asset Information>Asset Type>Vehicle>Digger, Company Group>Excavator/Tradestaff, Company Group>Machines, Company Group>Trade Staff | E30: Digger, Excavator/Tradestaff, Machines, Trade Staff | F30: Jay | G30: Libarnes | H30: jay.libarnes | I30: Standard Hours | J30: GO Mode,Garmin,HOS,Iridium,UI | K30: Stopped | L30: FALSE | M30: Morningside | N30: Morningside: 65 Morningside Rd, Northland Region 0110, New Zealand | O30: Project | Q30: 584.02374 | R30: 61.608334 | S30: 45842.407 | T30: 54789.542 | U30: Version 9 | V30: 120 | W30: 42 | X30: 57 | Y30: G94CDT2RF5R3 | AB30: FALSE | AC30: Off | AE30: ????????????????? | AF30: Pacific/Auckland | AG30: 6T Hitachi ZX65USB-5A 2022 | AH30: 45975.823 | AI30: 45975.845 | AL30: OK | AS30: 0 | AT30: 0 | AX30: VIN Error: CouldNotDecodeError;
A31: 143 | B31: b15F | C31: Digger, Excavator/Tradestaff, Machines, Trade Staff | D31: Company Group>Asset Information>Asset Type>Vehicle>Digger, Company Group>Excavator/Tradestaff, Company Group>Machines, Company Group>Trade Staff | E31: Digger, Excavator/Tradestaff, Machines, Trade Staff | I31: Standard Hours | J31: GO Mode,Garmin,HOS,Iridium,UI | K31: Stopped | L31: FALSE | M31: Kaikohe Work Area | N31: Kaikohe Work Area: 29 Wihongi Street, Kaikohe 0405, New Zealand | O31: Project | Q31: 439.50159 | R31: 57.83075 | S31: 45782.834 | T31: 54789.542 | U31: Version 9 | V31: 120 | W31: 42 | X31: 57 | Y31: G97CJZK7PW0N | AB31: FALSE | AC31: Off | AE31: @@@@@@@@@@@@@@@@@ | AF31: Pacific/Auckland | AG31: 2.6T Hitachi ZX26U-5A 2022 | AH31: 45974.483 | AI31: 45975.861 | AL31: OK | AS31: 0 | AT31: 0 | AX31: VIN Error: CouldNotDecodeError;
A32: 144 | B32: b172 | C32: Digger, Excavator/Tradestaff, Machines, Trade Staff | D32: Company Group>Asset Information>Asset Type>Equipment>Digger, Company Group>Excavator/Tradestaff, Company Group>Machines, Company Group>Trade Staff | E32: Digger, Excavator/Tradestaff, Machines, Trade Staff | I32: Standard Hours | J32: GO Mode,Garmin,HOS,Iridium,UI | K32: Stopped | L32: FALSE | M32: United Civil Head Office | N32: United Civil Head Office: 19B Rewa Rewa Road, Raumanga, Whangārei 0110, New Zealand | O32: Office Zone | Q32: 494.29266 | R32: 518.81555 | S32: 45782.841 | T32: 54789.542 | U32: Version 9 | V32: 120 | W32: 37 | X32: 27 | Y32: G9CH5398MV5N | AB32: FALSE | AC32: Off | AE32: @@@@@@@@@@@@@@@@@ | AF32: Pacific/Auckland | AG32: 14.5T Hyundai R145CRD-9 2012 | AH32: 45968.544 | AI32: 45968.545 | AL32: Device is not downloading data | AS32: 0 | AT32: 0 | AX32: VIN Error: CouldNotDecodeError;
A33: 146 | B33: b107 | C33: Electric Vehicles, Battery Electric Vehicle, Fuel Cell Electric Vehicle, Manually Classified Powertrain, Excavator/Tradestaff, Machines | D33: Company Group>Asset Information>Asset Type>Vehicle>Electric Vehicles, Company Group>Asset Information>Powertrain and Fuel Type>Electric or Plug-In Hybrid>Battery Electric Vehicle, Company Group>Asset Information>Powertrain and Fuel Type>Fuel Cell Electric Vehicle, Company Group>Asset Information>Powertrain and Fuel Type>Manually Classified Powertrain, Company Group>Excavator/Tradestaff, Company Group>Machines | E33: Battery Electric Vehicle, Electric Vehicles, Excavator/Tradestaff, Fuel Cell Electric Vehicle, Machines, Manually Classified Powertrain | I33: Standard Hours | J33: GO Mode,Garmin,HOS,Iridium,UI | K33: Stopped | L33: FALSE | M33: Channel Infrastructure,Channel Infrastructure,Asset Battery Drain | N33: Channel Infrastructure: 839 Port Marsden Highway, Marsden Point 0171, New Zealand | O33: Project | Q33: 11.266312 | R33: 7.1712034 | S33: 45724.473 | T33: 54789.542 | U33: Version 9 | V33: 120 | W33: 42 | X33: 55 | Y33: G918211C3B1E | AB33: FALSE | AC33: Off | AE33: ? | AF33: Pacific/Auckland | AG33: Etrucks EV Digger | AH33: 45919.362 | AI33: 45955.789 | AL33: Device is not downloading data | AS33: 0 | AT33: 0 | AX33: VIN Error: CouldNotDecodeError;
A34: 200 | B34: b16C | C34: Loader, Loader/Trade Staff, Machines | D34: Company Group>Asset Information>Asset Type>Vehicle>Loader, Company Group>Loader/Trade Staff, Company Group>Machines | E34: Loader, Loader/Trade Staff, Machines | F34: Moses | G34: Tito | H34: moses.tito | I34: Standard Hours | J34: GO Mode,Garmin,HOS,Iridium,UI | K34: Stopped | L34: FALSE | M34: Kaikohe | N34: Kaikohe: 13 Carey Road, Kaikohe 0474, New Zealand | O34: Project | Q34: 1218.7343 | R34: 339.09583 | S34: 45826.452 | T34: 54789.542 | U34: Version 9 | V34: 120 | W34: 42 | X34: 57 | Y34: G9XMUXRXUHFA | Z34: DNF822 | AB34: FALSE | AC34: Off | AE34: ````````````````` | AF34: Pacific/Auckland | AG34: 14T Hyundai HL757-7 2006 | AH34: 45975.646 | AI34: 45975.856 | AL34: OK | AS34: 0 | AT34: -979200 | AX34: VIN Error: CouldNotDecodeError;
A35: 202 | B35: b169 | C35: Loader, Loader/Trade Staff, Machines, Trade Staff | D35: Company Group>Asset Information>Asset Type>Vehicle>Loader, Company Group>Loader/Trade Staff, Company Group>Machines, Company Group>Trade Staff | E35: Loader, Loader/Trade Staff, Machines, Trade Staff | F35: Izak | G35: Proctor | H35: izak.proctor | I35: Standard Hours | J35: GO Mode,Garmin,HOS,Iridium,UI | K35: Stopped | L35: FALSE | M35: Gillingham Road,Gillingham Road | N35: Gillingham Road: 62A Gillingham Road, Te Kamo, Whangārei 0112, New Zealand | O35: Project | Q35: 33.721222 | R35: 140.67289 | S35: 45782.842 | T35: 54789.542 | U35: Version 9 | V35: 120 | W35: 42 | X35: 57 | Y35: G9H18PAP17UE | Z35: JJL907 | AB35: FALSE | AC35: Off | AE35: @@@@@@@@@@@@@@@@@ | AF35: Pacific/Auckland | AG35: 5T Kubota R520S 2014 | AH35: 45973.312 | AI35: 45975.666 | AL35: OK | AS35: 0 | AT35: 0 | AX35: VIN Error: CouldNotDecodeError;
A36: 203 | B36: b168 | C36: Loader, Loader/Trade Staff, Machines, Trade Staff | D36: Company Group>Asset Information>Asset Type>Vehicle>Loader, Company Group>Loader/Trade Staff, Company Group>Machines, Company Group>Trade Staff | E36: Loader, Loader/Trade Staff, Machines, Trade Staff | I36: Standard Hours | J36: GO Mode,Garmin,HOS,Iridium,UI | K36: Stopped | L36: FALSE | M36: Channel Infrastructure | N36: Channel Infrastructure: Timber Trail, Northland Region, New Zealand | O36: Project | Q36: 1046.3342 | R36: 158.27463 | S36: 45782.843 | T36: 54789.542 | U36: Version 9 | V36: 120 | W36: 42 | X36: 57 | Y36: G9N7PTSZASUX | Z36: B9BKT | AB36: FALSE | AC36: Off | AE36: @@@@@@@@@@@@@@@@@ | AF36: Pacific/Auckland | AG36: 3T Kubota R420S 2014 | AH36: 45975.657 | AI36: 45975.848 | AL36: OK | AS36: 0 | AT36: 0 | AX36: VIN Error: CouldNotDecodeError;
A37: 204 | B37: b307 | C37: Loader, Loader/Trade Staff | D37: Company Group>Asset Information>Asset Type>Vehicle>Loader, Company Group>Loader/Trade Staff | E37: Loader, Loader/Trade Staff | I37: Standard Hours | L37: FALSE | Q37: 0 | R37: 205.41667 | S37: 45959.563 | T37: 54789.542 | U37: None | V37: -1 | AB37: FALSE | AC37: NotApplicable | AF37: UTC | AG37: 18T Landex XCMG LW500K 2016 | AS37: 0 | AT37: 0 | AX37: VIN Error: CouldNotDecodeError;
A38: 206 | B38: b162 | C38: Loader, Machines, Telehandler/Trade Staff, Trade Staff | D38: Company Group>Asset Information>Asset Type>Vehicle>Loader, Company Group>Machines, Company Group>Telehandler/Trade Staff, Company Group>Trade Staff | E38: Loader, Machines, Telehandler/Trade Staff, Trade Staff | I38: Standard Hours | J38: GO Mode,Garmin,HOS,Iridium,UI | K38: Stopped | L38: FALSE | M38: Kaikohe | N38: Kaikohe: 8 Lindvart Street, Kaikohe 0474, New Zealand | O38: Project | Q38: 577.38269 | R38: 110.6875 | S38: 45782.843 | T38: 54789.542 | U38: Version 9 | V38: 120 | W38: 42 | X38: 57 | Y38: G9PMT34EV9EP | Z38: QPW244 | AB38: FALSE | AC38: Off | AE38: @@@@@@@@@@@@@@@@@ | AF38: Pacific/Auckland | AG38: 7T Manitou MLT-X732 | AH38: 45975.62 | AI38: 45975.851 | AL38: OK | AS38: 0 | AT38: 0 | AX38: VIN Error: CouldNotDecodeError;
A39: 207 | B39: b16D | C39: Loader, Machines, Telehandler/Trade Staff, Trade Staff | D39: Company Group>Asset Information>Asset Type>Vehicle>Loader, Company Group>Machines, Company Group>Telehandler/Trade Staff, Company Group>Trade Staff | E39: Loader, Machines, Telehandler/Trade Staff, Trade Staff | F39: Felix | G39: Bongalos | H39: felix.bongalos | I39: Standard Hours | J39: GO Mode,Garmin,HOS,Iridium,UI | K39: Stopped | L39: FALSE | M39: Channel Infrastructure | N39: Channel Infrastructure: 12 Ralph Trimmer Drive, Marsden Point 0171, New Zealand | O39: Project | Q39: 1619.0862 | R39: 118.57661 | S39: 45782.844 | T39: 54789.542 | U39: Version 9 | V39: 120 | W39: 42 | X39: 57 | Y39: G9VD67CSFR72 | Z39: QEG429 | AB39: FALSE | AC39: Off | AE39: @@@@@@@@@@@@@@@@@ | AF39: Pacific/Auckland | AG39: 5T Manitou MT625 | AH39: 45975.628 | AI39: 45975.859 | AL39: OK | AS39: 0 | AT39: 0 | AX39: VIN Error: CouldNotDecodeError;
A40: 208 | B40: b163 | C40: Loader, Machines, Telehandler/Trade Staff, Trade Staff | D40: Company Group>Asset Information>Asset Type>Vehicle>Loader, Company Group>Machines, Company Group>Telehandler/Trade Staff, Company Group>Trade Staff | E40: Loader, Machines, Telehandler/Trade Staff, Trade Staff | I40: Standard Hours | J40: GO Mode,Garmin,HOS,Iridium,UI | K40: Stopped | L40: FALSE | M40: Morningside | N40: Morningside: 80 Morningside Road, Morningside, Whangārei 0110, New Zealand | O40: Project | Q40: 102.41561 | R40: 70.130299 | S40: 45861.619 | T40: 54789.542 | U40: Version 9 | V40: 120 | W40: 37 | X40: 27 | Y40: G9AE0M2U2XW4 | Z40: QEG430 | AB40: FALSE | AC40: On | AE40: @@@@@@@@@@@@@@@@@ | AF40: Pacific/Auckland | AG40: 7T Manitou MLT-X732 | AH40: 45974.791 | AI40: 45975.857 | AL40: OK | AS40: 0 | AT40: 0 | AX40: VIN Error: CouldNotDecodeError;
...

Sheet Report
A1: Device Report | D1: =Data!B2 -> 45975.863
A2: =Data!B1 -> United Civil Construction Limited
A4: Report Time Zone | B4: =Data!B3 -> Pacific/Auckland
A5: Distance Unit | B5: =Data!B4 -> km
A7: Device | B7: Device Group | C7: Device ID | D7: First Name | E7: Last Name | F7: Current Driver | G7: Work time | H7: Current Activity | I7: In Privacy Mode | J7: Last Stop Address | K7: Last Stop Zone Types | L7: Current Odometer | M7: Current Engine Hours | N7: Active from | O7: Active to | P7: Is Archived (Historical) | Q7: Plan | R7: Device Type | S7: Firmware Version | T7: Serial No. | U7: License Plate | V7: License State/Province | W7: VIN | X7: Time Zone | Y7: Device Comment | Z7: Download Status | AA7: Last Trip | AB7: Last Communication Date
A8: =Data!A9 -> 1 | B8: =Data!C9 -> Vehicle, EV/Other Management | C8: =Data!B9 -> b2F2 | D8: =Data!F9 -> 0 | E8: =Data!G9 -> 0 | F8: =Data!H9 -> 0 | G8: =Data!I9 -> Standard Hours | H8: =Data!K9 -> 0 | I8: =Data!L9 -> FALSE | J8: =Data!N9 -> 0 | K8: =Data!O9 -> 0 | L8: =Data!Q9 -> 0 | M8: =Data!R9 -> 0 | N8: =Data!S9 -> 45948.893 | O8: =Data!T9 -> 54789.542 | P8: =OR(Data!$B$2<Data!S9,Data!$B$2>Data!T9) -> FALSE | Q8: =Data!J9 -> Terminate Mode,UI | R8: =Data!U9 -> Version 9 | S8: =CONCATENATE(Data!V9,".",Data!W9,".",Data!X9) -> 120.0.0 | T8: =Data!Y9 -> G9W1PJSDBFNV | U8: =Data!Z9 -> 0 | V8: =Data!AA9 -> 0 | W8: =Data!AD9 -> 0 | X8: =Data!AF9 -> UTC | Y8: =IF(ISBLANK(Data!AG9),"",Data!AG9) | Z8: =Data!AL9 -> 0 | AA8: =Data!AH9 -> 0 | AB8: =IF(ISBLANK(Data!AI9),"",Data!AI9)
A9: =Data!A10 -> 103 | B9: =Data!C10 -> Digger, Excavator/Tradestaff, Machines, Trade Staff | C9: =Data!B10 -> b161 | D9: =Data!F10 -> 0 | E9: =Data!G10 -> 0 | F9: =Data!H10 -> 0 | G9: =Data!I10 -> Standard Hours | H9: =Data!K10 -> Stopped | I9: =Data!L10 -> FALSE | J9: =Data!N10 -> Channel Infrastructure: 41 Mair Road, Marsden Point 0171, New Zealand | K9: =Data!O10 -> Project | L9: =Data!Q10 -> 283.65958 | M9: =Data!R10 -> 348.29408 | N9: =Data!S10 -> 45782.821 | O9: =Data!T10 -> 54789.542 | P9: =OR(Data!$B$2<Data!S10,Data!$B$2>Data!T10) -> FALSE | Q9: =Data!J10 -> GO Mode,Garmin,HOS,Iridium,UI | R9: =Data!U10 -> Version 9 | S9: =CONCATENATE(Data!V10,".",Data!W10,".",Data!X10) -> 120.42.57 | T9: =Data!Y10 -> G9JS3X5N41M7 | U9: =Data!Z10 -> EUG563 | V9: =Data!AA10 -> 0 | W9: =Data!AD10 -> 0 | X9: =Data!AF10 -> Pacific/Auckland | Y9: =IF(ISBLANK(Data!AG10),"",Data!AG10) -> 14T Hitachi ZX140W-3 2009 | Z9: =Data!AL10 -> OK | AA9: =Data!AH10 -> 45974.543 | AB9: =IF(ISBLANK(Data!AI10),"",Data!AI10) -> 45975.849
A10: =Data!A11 -> 1080 | B10: =Data!C11 -> Generator, Generator/Trade Staff, Trade Staff | C10: =Data!B11 -> b2C5 | D10: =Data!F11 -> 0 | E10: =Data!G11 -> 0 | F10: =Data!H11 -> 0 | G10: =Data!I11 -> Standard Hours | H10: =Data!K11 -> 0 | I10: =Data!L11 -> FALSE | J10: =Data!N11 -> 0 | K10: =Data!O11 -> 0 | L10: =Data!Q11 -> 0 | M10: =Data!R11 -> 0 | N10: =Data!S11 -> 45929.439 | O10: =Data!T11 -> 54789.542 | P10: =OR(Data!$B$2<Data!S11,Data!$B$2>Data!T11) -> FALSE | Q10: =Data!J11 -> 0 | R10: =Data!U11 -> None | S10: =CONCATENATE(Data!V11,".",Data!W11,".",Data!X11) -> -1.. | T10: =Data!Y11 -> 0 | U10: =Data!Z11 -> 0 | V10: =Data!AA11 -> 0 | W10: =Data!AD11 -> 0 | X10: =Data!AF11 -> UTC | Y10: =IF(ISBLANK(Data!AG11),"",Data!AG11) -> P9 Fox | Z10: =Data!AL11 -> 0 | AA10: =Data!AH11 -> 0 | AB10: =IF(ISBLANK(Data!AI11),"",Data!AI11)
A11: =Data!A12 -> 1081 | B11: =Data!C12 -> Generator, Generator/Trade Staff, Trade Staff | C11: =Data!B12 -> b2C6 | D11: =Data!F12 -> 0 | E11: =Data!G12 -> 0 | F11: =Data!H12 -> 0 | G11: =Data!I12 -> Standard Hours | H11: =Data!K12 -> 0 | I11: =Data!L12 -> FALSE | J11: =Data!N12 -> 0 | K11: =Data!O12 -> 0 | L11: =Data!Q12 -> 0 | M11: =Data!R12 -> 521.54167 | N11: =Data!S12 -> 45929.44 | O11: =Data!T12 -> 54789.542 | P11: =OR(Data!$B$2<Data!S12,Data!$B$2>Data!T12) -> FALSE | Q11: =Data!J12 -> 0 | R11: =Data!U12 -> None | S11: =CONCATENATE(Data!V12,".",Data!W12,".",Data!X12) -> -1.. | T11: =Data!Y12 -> 0 | U11: =Data!Z12 -> 0 | V11: =Data!AA12 -> 0 | W11: =Data!AD12 -> 0 | X11: =Data!AF12 -> UTC | Y11: =IF(ISBLANK(Data!AG12),"",Data!AG12) -> P15 Fox | Z11: =Data!AL12 -> 0 | AA11: =Data!AH12 -> 0 | AB11: =IF(ISBLANK(Data!AI12),"",Data!AI12)
A12: =Data!A13 -> 111 | B12: =Data!C13 -> Digger, Battery Electric Vehicle, Excavator/Tradestaff, Machines | C12: =Data!B13 -> b176 | D12: =Data!F13 -> Archie | E12: =Data!G13 -> Abellana | F12: =Data!H13 -> archie.abellana | G12: =Data!I13 -> Standard Hours | H12: =Data!K13 -> Stopped | I12: =Data!L13 -> FALSE | J12: =Data!N13 -> Gillingham Road: 75 Gillingham Road, Te Kamo, Whangārei 0112, New Zealand | K12: =Data!O13 -> Project | L12: =Data!Q13 -> 153.15073 | M12: =Data!R13 -> 344.52307 | N12: =Data!S13 -> 45842.406 | O12: =Data!T13 -> 54789.542 | P12: =OR(Data!$B$2<Data!S13,Data!$B$2>Data!T13) -> FALSE | Q12: =Data!J13 -> GO Mode,Garmin,HOS,Iridium,UI | R12: =Data!U13 -> Version 9 | S12: =CONCATENATE(Data!V13,".",Data!W13,".",Data!X13) -> 120.42.57 | T12: =Data!Y13 -> G9RHXM0XNPXP | U12: =Data!Z13 -> 0 | V12: =Data!AA13 -> 0 | W12: =Data!AD13 -> 0 | X12: =Data!AF13 -> Pacific/Auckland | Y12: =IF(ISBLANK(Data!AG13),"",Data!AG13) -> 13.5T Hitachi ZX135USLC-3 2012 | Z12: =Data!AL13 -> OK | AA12: =Data!AH13 -> 45975.659 | AB12: =IF(ISBLANK(Data!AI13),"",Data!AI13) -> 45975.848
A13: =Data!A14 -> 1141 | B13: =Data!C14 -> Generator, Generator/Trade Staff, Trade Staff | C13: =Data!B14 -> b2C7 | D13: =Data!F14 -> 0 | E13: =Data!G14 -> 0 | F13: =Data!H14 -> 0 | G13: =Data!I14 -> Standard Hours | H13: =Data!K14 -> 0 | I13: =Data!L14 -> FALSE | J13: =Data!N14 -> 0 | K13: =Data!O14 -> 0 | L13: =Data!Q14 -> 0 | M13: =Data!R14 -> 0 | N13: =Data!S14 -> 45929.44 | O13: =Data!T14 -> 54789.542 | P13: =OR(Data!$B$2<Data!S14,Data!$B$2>Data!T14) -> FALSE | Q13: =Data!J14 -> 0 | R13: =Data!U14 -> None | S13: =CONCATENATE(Data!V14,".",Data!W14,".",Data!X14) -> -1.. | T13: =Data!Y14 -> 0 | U13: =Data!Z14 -> 0 | V13: =Data!AA14 -> 0 | W13: =Data!AD14 -> 0 | X13: =Data!AF14 -> UTC | Y13: =IF(ISBLANK(Data!AG14),"",Data!AG14) | Z13: =Data!AL14 -> 0 | AA13: =Data!AH14 -> 0 | AB13: =IF(ISBLANK(Data!AI14),"",Data!AI14)
A14: =Data!A15 -> 122 | B14: =Data!C15 -> Digger, Excavator/Tradestaff, Machines, Trade Staff | C14: =Data!B15 -> b164 | D14: =Data!F15 -> 0 | E14: =Data!G15 -> 0 | F14: =Data!H15 -> 0 | G14: =Data!I15 -> Standard Hours | H14: =Data!K15 -> Stopped | I14: =Data!L15 -> FALSE | J14: =Data!N15 -> Kaitaia Wastewater: 10 Puckey Avenue, Kaitaia 0410, New Zealand | K14: =Data!O15 -> Project | L14: =Data!Q15 -> 398.496 | M14: =Data!R15 -> 277.74583 | N14: =Data!S15 -> 45782.825 | O14: =Data!T15 -> 54789.542 | P14: =OR(Data!$B$2<Data!S15,Data!$B$2>Data!T15) -> FALSE | Q14: =Data!J15 -> GO Mode,Garmin,HOS,Iridium,UI | R14: =Data!U15 -> Version 9 | S14: =CONCATENATE(Data!V15,".",Data!W15,".",Data!X15) -> 120.42.57 | T14: =Data!Y15 -> G9071KVMB37P | U14: =Data!Z15 -> 0 | V14: =Data!AA15 -> 0 | W14: =Data!AD15 -> 0 | X14: =Data!AF15 -> Pacific/Auckland | Y14: =IF(ISBLANK(Data!AG15),"",Data!AG15) -> 5.5T Hitachi ZX55U-5 2014 | Z14: =Data!AL15 -> OK | AA14: =Data!AH15 -> 45967.487 | AB14: =IF(ISBLANK(Data!AI15),"",Data!AI15) -> 45975.469
A15: =Data!A16 -> 123 | B15: =Data!C16 -> Digger, Excavator/Tradestaff, Machines, Trade Staff | C15: =Data!B16 -> b16A | D15: =Data!F16 -> 0 | E15: =Data!G16 -> 0 | F15: =Data!H16 -> 0 | G15: =Data!I16 -> Standard Hours | H15: =Data!K16 -> Stopped | I15: =Data!L16 -> FALSE | J15: =Data!N16 -> Channel Infrastructure: 41 Mair Road, Marsden Point 0171, New Zealand | K15: =Data!O16 -> Project | L15: =Data!Q16 -> 41.567631 | M15: =Data!R16 -> 125.61197 | N15: =Data!S16 -> 45782.835 | O15: =Data!T16 -> 54789.542 | P15: =OR(Data!$B$2<Data!S16,Data!$B$2>Data!T16) -> FALSE | Q15: =Data!J16 -> GO Mode,Garmin,HOS,Iridium,UI | R15: =Data!U16 -> Version 9 | S15: =CONCATENATE(Data!V16,".",Data!W16,".",Data!X16) -> 120.42.57 | T15: =Data!Y16 -> G9F8JM3179FZ | U15: =Data!Z16 -> 0 | V15: =Data!AA16 -> 0 | W15: =Data!AD16 -> 0 | X15: =Data!AF16 -> Pacific/Auckland | Y15: =IF(ISBLANK(Data!AG16),"",Data!AG16) -> 1.7T Hitachi ZX17U-2 2014 | Z15: =Data!AL16 -> OK | AA15: =Data!AH16 -> 45974.547 | AB15: =IF(ISBLANK(Data!AI16),"",Data!AI16) -> 45975.842
A16: =Data!A17 -> 124 | B16: =Data!C17 -> Digger, Diesel, Excavator/Tradestaff, Machines, Trade Staff | C16: =Data!B17 -> b166 | D16: =Data!F17 -> 0 | E16: =Data!G17 -> 0 | F16: =Data!H17 -> 0 | G16: =Data!I17 -> Standard Hours | H16: =Data!K17 -> Stopped | I16: =Data!L17 -> FALSE | J16: =Data!N17 -> Morningside: 65 Morningside Rd, Northland Region 0110, New Zealand | K16: =Data!O17 -> Project | L16: =Data!Q17 -> 229.87764 | M16: =Data!R17 -> 388.45 | N16: =Data!S17 -> 45782.834 | O16: =Data!T17 -> 54789.542 | P16: =OR(Data!$B$2<Data!S17,Data!$B$2>Data!T17) -> FALSE | Q16: =Data!J17 -> GO Mode,Garmin,HOS,Iridium,UI | R16: =Data!U17 -> Version 9 | S16: =CONCATENATE(Data!V17,".",Data!W17,".",Data!X17) -> 120.42.57 | T16: =Data!Y17 -> G9EKK0KRFU3Y | U16: =Data!Z17 -> 0 | V16: =Data!AA17 -> 0 | W16: =Data!AD17 -> 0 | X16: =Data!AF17 -> Pacific/Auckland | Y16: =IF(ISBLANK(Data!AG17),"",Data!AG17) -> 23.5T Hyundai R235 LCR-9 2014 | Z16: =Data!AL17 -> OK | AA16: =Data!AH17 -> 45975.821 | AB16: =IF(ISBLANK(Data!AI17),"",Data!AI17) -> 45975.844
A17: =Data!A18 -> 128 | B17: =Data!C18 -> Digger, Diesel, Excavator/Tradestaff, Machines, Trade Staff | C17: =Data!B18 -> b170 | D17: =Data!F18 -> 0 | E17: =Data!G18 -> 0 | F17: =Data!H18 -> 0 | G17: =Data!I18 -> Standard Hours | H17: =Data!K18 -> Stopped | I17: =Data!L18 -> FALSE | J17: =Data!N18 -> Morningside: 65 Morningside Rd, Northland Region 0110, New Zealand | K17: =Data!O18 -> Project | L17: =Data!Q18 -> 265.51221 | M17: =Data!R18 -> 322.36667 | N17: =Data!S18 -> 45782.834 | O17: =Data!T18 -> 54789.542 | P17: =OR(Data!$B$2<Data!S18,Data!$B$2>Data!T18) -> FALSE | Q17: =Data!J18 -> GO Mode,Garmin,HOS,Iridium,UI | R17: =Data!U18 -> Version 9 | S17: =CONCATENATE(Data!V18,".",Data!W18,".",Data!X18) -> 120.42.57 | T17: =Data!Y18 -> G9USRCKV6BVV | U17: =Data!Z18 -> 0 | V17: =Data!AA18 -> 0 | W17: =Data!AD18 -> 0 | X17: =Data!AF18 -> Pacific/Auckland | Y17: =IF(ISBLANK(Data!AG18),"",Data!AG18) -> 23.5T Hyundai R235LCR-9 2016 | Z17: =Data!AL18 -> OK | AA17: =Data!AH18 -> 45975.742 | AB17: =IF(ISBLANK(Data!AI18),"",Data!AI18) -> 45975.847
A18: =Data!A19 -> 129 | B18: =Data!C19 -> Digger, Excavator/Tradestaff, Machines, Trade Staff | C18: =Data!B19 -> b160 | D18: =Data!F19 -> 0 | E18: =Data!G19 -> 0 | F18: =Data!H19 -> 0 | G18: =Data!I19 -> Standard Hours | H18: =Data!K19 -> Stopped | I18: =Data!L19 -> FALSE | J18: =Data!N19 -> Kaitaia Wastewater: 1 Bonnetts Road, Kaitaia 0410, New Zealand | K18: =Data!O19 -> Project | L18: =Data!Q19 -> 244.47006 | M18: =Data!R19 -> 6.0732569 | N18: =Data!S19 -> 45782.834 | O18: =Data!T19 -> 54789.542 | P18: =OR(Data!$B$2<Data!S19,Data!$B$2>Data!T19) -> FALSE | Q18: =Data!J19 -> GO Mode,Garmin,HOS,Iridium,UI | R18: =Data!U19 -> Version 9 | S18: =CONCATENATE(Data!V19,".",Data!W19,".",Data!X19) -> 120.42.57 | T18: =Data!Y19 -> G940DTZJ0XM1 | U18: =Data!Z19 -> 0 | V18: =Data!AA19 -> 0 | W18: =Data!AD19 -> 0 | X18: =Data!AF19 -> Pacific/Auckland | Y18: =IF(ISBLANK(Data!AG19),"",Data!AG19) -> 1.7T Hyundai R17z-19A 2017 | Z18: =Data!AL19 -> OK | AA18: =Data!AH19 -> 45975.334 | AB18: =IF(ISBLANK(Data!AI19),"",Data!AI19) -> 45975.863
A19: =Data!A20 -> 130 | B19: =Data!C20 -> Digger, Excavator/Tradestaff, Machines, Trade Staff | C19: =Data!B20 -> b16E | D19: =Data!F20 -> 0 | E19: =Data!G20 -> 0 | F19: =Data!H20 -> 0 | G19: =Data!I20 -> Standard Hours | H19: =Data!K20 -> Stopped | I19: =Data!L20 -> FALSE | J19: =Data!N20 -> Ngawha: 73B Bannister Road, Ngawha Springs 0472, New Zealand | K19: =Data!O20 -> Project | L19: =Data!Q20 -> 549.59198 | M19: =Data!R20 -> 88.830679 | N19: =Data!S20 -> 45782.835 | O19: =Data!T20 -> 54789.542 | P19: =OR(Data!$B$2<Data!S20,Data!$B$2>Data!T20) -> FALSE | Q19: =Data!J20 -> GO Mode,Garmin,HOS,Iridium,UI | R19: =Data!U20 -> Version 9 | S19: =CONCATENATE(Data!V20,".",Data!W20,".",Data!X20) -> 120.42.57 | T19: =Data!Y20 -> G9K3YS8BXU3J | U19: =Data!Z20 -> 0 | V19: =Data!AA20 -> 0 | W19: =Data!AD20 -> 0 | X19: =Data!AF20 -> Pacific/Auckland | Y19: =IF(ISBLANK(Data!AG20),"",Data!AG20) -> 1.7T Hyundai R17z-19A 2017 | Z19: =Data!AL20 -> OK | AA19: =Data!AH20 -> 45974.572 | AB19: =IF(ISBLANK(Data!AI20),"",Data!AI20) -> 45975.856
... A140: =Data!A141 -> Hired Truck | B140: =Data!C141 -> Heavy Diesel Vehicles, HDV/Trade Staff, Trade Staff | C140: =Data!B141 -> b26E | D140: =Data!F141 -> 0 | E140: =Data!G141 -> 0 | F140: =Data!H141 -> 0 | G140: =Data!I141 -> Standard Hours | H140: =Data!K141 -> 0 | I140: =Data!L141 -> FALSE | J140: =Data!N141 -> 0 | K140: =Data!O141 -> 0 | L140: =Data!Q141 -> 0 | M140: =Data!R141 -> 0 | N140: =Data!S141 -> 45889.423 | O140: =Data!T141 -> 54789.542 | P140: =OR(Data!$B$2<Data!S141,Data!$B$2>Data!T141) -> FALSE | Q140: =Data!J141 -> 0 | R140: =Data!U141 -> None | S140: =CONCATENATE(Data!V141,".",Data!W141,".",Data!X141) -> -1.. | T140: =Data!Y141 -> 0 | U140: =Data!Z141 -> 0 | V140: =Data!AA141 -> 0 | W140: =Data!AD141 -> 2 | X140: =Data!AF141 -> UTC | Y140: =IF(ISBLANK(Data!AG141),"",Data!AG141) | Z140: =Data!AL141 -> 0 | AA140: =Data!AH141 -> 0 | AB140: =IF(ISBLANK(Data!AI141),"",Data!AI141)

Sheet Summary
A1: Device Report | C1: =Data!B2 -> 45975.863
A2: =Data!B1 -> United Civil Construction Limited
A4: Report Time Zone | B4: =Data!B3 -> Pacific/Auckland
A5: Distance Unit | B5: =Data!B4 -> km
A7: Device | B7: Device Group | C7: Current Odometer | D7: Active from | E7: Active to | F7: Device Type | G7: Firmware Version | H7: Serial No. | I7: License Plate | J7: License State/Province | K7: VIN | L7: Time Zone
A8: 1 | B8: Vehicle, EV/Other Management | C8: 0 | D8: 45948.893 | E8: 54789.542 | F8: Version 9 | G8: 120.0.0 | H8: G9W1PJSDBFNV | I8: 0 | J8: 0 | K8: 0 | L8: UTC
A9: 103 | B9: Digger, Excavator/Tradestaff, Machines, Trade Staff | C9: 283.65958 | D9: 45782.821 | E9: 54789.542 | F9: Version 9 | G9: 120.42.57 | H9: G9JS3X5N41M7 | I9: EUG563 | J9: 0 | K9: 0 | L9: Pacific/Auckland
A10: 1080 | B10: Generator, Generator/Trade Staff, Trade Staff | C10: 0 | D10: 45929.439 | E10: 54789.542 | F10: None | G10: -1.. | H10: 0 | I10: 0 | J10: 0 | K10: 0 | L10: UTC
A11: 1081 | B11: Generator, Generator/Trade Staff, Trade Staff | C11: 0 | D11: 45929.44 | E11: 54789.542 | F11: None | G11: -1.. | H11: 0 | I11: 0 | J11: 0 | K11: 0 | L11: UTC
A12: 111 | B12: Digger, Battery Electric Vehicle, Excavator/Tradestaff, Machines | C12: 153.15073 | D12: 45842.406 | E12: 54789.542 | F12: Version 9 | G12: 120.42.57 | H12: G9RHXM0XNPXP | I12: 0 | J12: 0 | K12: 0 | L12: Pacific/Auckland
A13: 1141 | B13: Generator, Generator/Trade Staff, Trade Staff | C13: 0 | D13: 45929.44 | E13: 54789.542 | F13: None | G13: -1.. | H13: 0 | I13: 0 | J13: 0 | K13: 0 | L13: UTC
A14: 122 | B14: Digger, Excavator/Tradestaff, Machines, Trade Staff | C14: 398.496 | D14: 45782.825 | E14: 54789.542 | F14: Version 9 | G14: 120.42.57 | H14: G9071KVMB37P | I14: 0 | J14: 0 | K14: 0 | L14: Pacific/Auckland
A15: 123 | B15: Digger, Excavator/Tradestaff, Machines, Trade Staff | C15: 41.567631 | D15: 45782.835 | E15: 54789.542 | F15: Version 9 | G15: 120.42.57 | H15: G9F8JM3179FZ | I15: 0 | J15: 0 | K15: 0 | L15: Pacific/Auckland
A16: 124 | B16: Digger, Diesel, Excavator/Tradestaff, Machines, Trade Staff | C16: 229.87764 | D16: 45782.834 | E16: 54789.542 | F16: Version 9 | G16: 120.42.57 | H16: G9EKK0KRFU3Y | I16: 0 | J16: 0 | K16: 0 | L16: Pacific/Auckland
A17: 128 | B17: Digger, Diesel, Excavator/Tradestaff, Machines, Trade Staff | C17: 265.51221 | D17: 45782.834 | E17: 54789.542 | F17: Version 9 | G17: 120.42.57 | H17: G9USRCKV6BVV | I17: 0 | J17: 0 | K17: 0 | L17: Pacific/Auckland
A18: 129 | B18: Digger, Excavator/Tradestaff, Machines, Trade Staff | C18: 244.47006 | D18: 45782.834 | E18: 54789.542 | F18: Version 9 | G18: 120.42.57 | H18: G940DTZJ0XM1 | I18: 0 | J18: 0 | K18: 0 | L18: Pacific/Auckland
A19: 130 | B19: Digger, Excavator/Tradestaff, Machines, Trade Staff | C19: 549.59198 | D19: 45782.835 | E19: 54789.542 | F19: Version 9 | G19: 120.42.57 | H19: G9K3YS8BXU3J | I19: 0 | J19: 0 | K19: 0 | L19: Pacific/Auckland
A20: 1304 | B20: Pump, Pump/Trade Staff, Trade Staff | C20: 0 | D20: 45929.442 | E20: 54789.542 | F20: None | G20: -1.. | H20: 0 | I20: 0 | J20: 0 | K20: 0 | L20: UTC
A21: 132 | B21: Digger, Excavator/Tradestaff, Machines, Trade Staff | C21: 132.82076 | D21: 45782.835 | E21: 54789.542 | F21: Version 9 | G21: 120.42.57 | H21: G98ZPSY1BD3K | I21: 0 | J21: 0 | K21: 0 | L21: Pacific/Auckland
A22: 133 | B22: Digger, Diesel, Excavator/Tradestaff, Machines, Trade Staff | C22: 307.37079 | D22: 45782.835 | E22: 54789.542 | F22: Version 9 | G22: 120.42.57 | H22: G9JN6AVZ9WNA | I22: 0 | J22: 0 | K22: 0 | L22: Pacific/Auckland
A23: 134 | B23: Digger, Excavator/Tradestaff, Machines, Trade Staff | C23: 353.31464 | D23: 45782.836 | E23: 54789.542 | F23: Version 9 | G23: 120.42.57 | H23: G9AXAZ5WJSNC | I23: 0 | J23: 0 | K23: 0 | L23: Pacific/Auckland
A24: 137 | B24: Digger, Excavator/Tradestaff, Machines, Trade Staff | C24: 361.92508 | D24: 45782.836 | E24: 54789.542 | F24: Version 9 | G24: 120.42.57 | H24: G960M159TRJS | I24: 0 | J24: 0 | K24: 0 | L24: Pacific/Auckland
A25: 138 | B25: Digger, Diesel, Excavator/Tradestaff, Machines, Trade Staff | C25: 218.2724 | D25: 45782.836 | E25: 54789.542 | F25: Version 9 | G25: 120.42.57 | H25: G9ZT0W7U7AX9 | I25: 0 | J25: 0 | K25: 0 | L25: Pacific/Auckland
A26: 139 | B26: Digger, Diesel, Excavator/Tradestaff, Machines, Trade Staff | C26: 201.37395 | D26: 45782.837 | E26: 54789.542 | F26: Version 9 | G26: 120.42.57 | H26: G9KESM7CCB7P | I26: 0 | J26: 0 | K26: 0 | L26: Pacific/Auckland
A27: 140 | B27: Digger, Excavator/Tradestaff, Machines, Trade Staff | C27: 10.799479 | D27: 45782.839 | E27: 54789.542 | F27: Version 9 | G27: 120.42.57 | H27: G95WT8P1KVE4 | I27: 0 | J27: 0 | K27: 0 | L27: Pacific/Auckland
A28: 141 | B28: Digger, Excavator/Tradestaff, Machines, Trade Staff | C28: 1909.9972 | D28: 45782.839 | E28: 54789.542 | F28: Version 9 | G28: 120.42.57 | H28: G97JWZZS6MBT | I28: 0 | J28: 0 | K28: 0 | L28: Pacific/Auckland
A29: 142 | B29: Digger, Excavator/Tradestaff, Machines, Trade Staff | C29: 584.02374 | D29: 45842.407 | E29: 54789.542 | F29: Version 9 | G29: 120.42.57 | H29: G94CDT2RF5R3 | I29: 0 | J29: 0 | K29: 0 | L29: Pacific/Auckland
A30: 143 | B30: Digger, Excavator/Tradestaff, Machines, Trade Staff | C30: 439.50159 | D30: 45782.834 | E30: 54789.542 | F30: Version 9 | G30: 120.42.57 | H30: G97CJZK7PW0N | I30: 0 | J30: 0 | K30: 0 | L30: Pacific/Auckland
A31: 144 | B31: Digger, Excavator/Tradestaff, Machines, Trade Staff | C31: 494.29266 | D31: 45782.841 | E31: 54789.542 | F31: Version 9 | G31: 120.37.27 | H31: G9CH5398MV5N | I31: 0 | J31: 0 | K31: 0 | L31: Pacific/Auckland
A32: 146 | B32: Electric Vehicles, Battery Electric Vehicle, Fuel Cell Electric Vehicle, Manually Classified Powertrain, Excavator/Tradestaff, Machines | C32: 11.266312 | D32: 45724.473 | E32: 54789.542 | F32: Version 9 | G32: 120.42.55 | H32: G918211C3B1E | I32: 0 | J32: 0 | K32: 0 | L32: Pacific/Auckland
A33: 200 | B33: Loader, Loader/Trade Staff, Machines | C33: 1218.7343 | D33: 45826.452 | E33: 54789.542 | F33: Version 9 | G33: 120.42.57 | H33: G9XMUXRXUHFA | I33: DNF822 | J33: 0 | K33: 0 | L33: Pacific/Auckland
A34: 202 | B34: Loader, Loader/Trade Staff, Machines, Trade Staff | C34: 33.721222 | D34: 45782.842 | E34: 54789.542 | F34: Version 9 | G34: 120.42.57 | H34: G9H18PAP17UE | I34: JJL907 | J34: 0 | K34: 0 | L34: Pacific/Auckland
A35: 203 | B35: Loader, Loader/Trade Staff, Machines, Trade Staff | C35: 1046.3342 | D35: 45782.843 | E35: 54789.542 | F35: Version 9 | G35: 120.42.57 | H35: G9N7PTSZASUX | I35: B9BKT | J35: 0 | K35: 0 | L35: Pacific/Auckland
A36: 204 | B36: Loader, Loader/Trade Staff | C36: 0 | D36: 45959.563 | E36: 54789.542 | F36: None | G36: -1.. | H36: 0 | I36: 0 | J36: 0 | K36: 0 | L36: UTC
A37: 206 | B37: Loader, Machines, Telehandler/Trade Staff, Trade Staff | C37: 577.38269 | D37: 45782.843 | E37: 54789.542 | F37: Version 9 | G37: 120.42.57 | H37: G9PMT34EV9EP | I37: QPW244 | J37: 0 | K37: 0 | L37: Pacific/Auckland
A38: 207 | B38: Loader, Machines, Telehandler/Trade Staff, Trade Staff | C38: 1619.0862 | D38: 45782.844 | E38: 54789.542 | F38: Version 9 | G38: 120.42.57 | H38: G9VD67CSFR72 | I38: QEG429 | J38: 0 | K38: 0 | L38: Pacific/Auckland
A39: 208 | B39: Loader, Machines, Telehandler/Trade Staff, Trade Staff | C39: 102.41561 | D39: 45861.619 | E39: 54789.542 | F39: Version 9 | G39: 120.37.27 | H39: G9AE0M2U2XW4 | I39: QEG430 | J39: 0 | K39: 0 | L39: Pacific/Auckland
A40: 209 | B40: Loader, Machines, Telehandler/Trade Staff, Trade Staff | C40: 525.92377 | D40: 45782.846 | E40: 54789.542 | F40: Version 9 | G40: 120.42.57 | H40: G9RS70FNPW7W | I40: QEG431 | J40: 0 | K40: 0 | L40: Pacific/Auckland
A41: 210 | B41: Loader, Diesel, Loader/Trade Staff, Machines, Trade Staff | C41: 513.34998 | D41: 45895.666 | E41: 54789.542 | F41: Version 9 | G41: 120.42.57 | H41: G9S1YZ20ERNN | I41: 0 | J41: 0 | K41: 0 | L41: Pacific/Auckland
A42: 3414 | B42: Heavy Diesel Vehicles, HDV/Trade Staff, Machines, Trade Staff | C42: 171325.34 | D42: 45782.958 | E42: 54789.542 | F42: Version 9 | G42: 120.42.57 | H42: G9R2VNN6AEF6 | I42: 0 | J42: 0 | K42: 0 | L42: Pacific/Auckland
...

Sheet Languages
A1: English | B1: French Canada | C1: Spanish | D1: German | E1: Japanese | F1: Polish | G1: Portuguese-Brazil | H1: Dutch | I1: Italian | J1: Simplified Chinese | K1: Thai | L1: Indonesian | M1: Czech | N1: Swedish | O1: Turkish | P1: Malay | Q1: French France | R1: Korean | S1: Traditional Chinese
A2: **Device | B2: Dispositif | C2: Dispositivo | D2: Gerät | E2: デバイス | F2: Urzadzenie | G2: Dispositivo | H2: Apparaat | I2: Dispositivo | J2: 设备 | K2: อุปกรณ์ | L2: Perangkat | M2: Zařízení | N2: Enhet | O2: Aygıt | P2: Peranti | Q2: Boîtier | R2: 장치 | S2: 裝置
A3: **First Name | B3: Prénom | C3: Nombre | D3: Vorname | E3: ファーストネー | F3: Imie | G3: Nome | H3: Voornaam | I3: Nome | J3: 名字 | K3: ชื่อ | L3: Nama Depan | M3: Křestní jméno | N3: Förnamn | O3: Ad | P3: Nama pertama | Q3: Prénom | R3: 이름 | S3: 名字
A4: **Last Name | B4: Nom de famille | C4: Apellido | D4: Nachname | E4: ラストネーム | F4: Nazwisko | G4: Sobrenome | H4: Achternaam | I4: Cognome | J4: 姓氏 | K4: นามสกุล | L4: Nama belakang | M4: Příjmení | N4: Efternamn | O4: Soyadı | P4: Nama keluarga | Q4: Nom de famille | R4: 성 | S4: 姓氏
A5: **Device Group | B5: Groupe de dispositifs | C5: Grupo de dispositivos | D5: Gerätegruppe | E5: デバイスグループ | F5: Grupa urzadzen | G5: Grupo de dispositivo | H5: Apparaatgroep | I5: Gruppo di dispositivi | J5: 设备的组名 | K5: กลุ่มอุปกรณ์ | L5: Grup Perangkat | M5: Skupina zařízení | N5: Enhetsgrupp | O5: Aygıt Grubu | P5: Kumpulan Peranti | Q5: Groupe de boîtiers | R5: 장치 그룹 | S5: 裝置群組
A6: **Current Driver | B6: Chauffeur actuel | C6: Conductor actual | D6: Aktueller Fahrer | E6: 現在のドライバー | F6: Aktualny kierowca | G6: Motorista atual | H6: Huidige chauffeur | I6: Conducente attuale | J6: 当前驾驶员 | K6: ผู้ขับปัจจุบัน | L6: Pengemudi Saat Ini | M6: Aktuální řidič | N6: Aktuell förare | O6: Geçerli Sürücü | P6: Pemandu semasa | Q6: Conducteur actuel | R6: 현재 운전자 | S6: 目前駕駛
A7: **Current Activity | B7: Activité actuelle | C7: Actividad actual | D7: Aktuelle Aktivität | E7: 現在のアクティビティ | F7: Aktualna aktywnosc | G7: Atividade atual | H7: Huidige activiteit | I7: Attività attuale | J7: 当前活动 | K7: กิจกรรมปัจจุบัน | L7: Aktivitas Saat Ini | M7: Aktuální aktivita | N7: Nuvarande aktivitet | O7: Geçerli Etkinlik | P7: Aktiviti Semasa | Q7: Activité actuelle | R7: 현재 활동 | S7: 目前活動
A8: **Last Stop Address | B8: Adresse du dernier arrêt | C8: Dirección de la última parada | D8: Adresse letzter Stopp | E8: 最終停車地の住所 | F8: Ostatni adres postoju | G8: Último endereço de parada | H8: Laatste stopadres | I8: Indirizzo dell'ultima sosta | J8: 上次停车地址 | K8: ที่อยู่ที่หยุดครั้งสุดท้าย | L8: Last Stop Address | M8: Adresa poslední zastávky | N8: Senaste stoppadress | O8: Son Duraklama Adresi | P8: Alamat Hentian Terakhir | Q8: Adresse du dernier arrêt | R8: 마지막 정지 주소 | S8: 上次停靠站地址
A9: **Last Stop Zone Types | B9: Type de zones du dernier arrêt | C9: Tipos de zona de la última parada | D9: Zonentyp letzter Stopp | E9: 最終停車地のゾーンタイプ | F9: Typy stref ostatniego postoju | G9: Últimos tipos da zona de parada | H9: Types laatste stopzone | I9: Tipi di zona dell'ultima sosta | J9: 上次停车区类型 | K9: ประเภทโซนที่หยุดครั้งสุดท้าย | L9: Last Stop Zone Types | M9: Typy zón poslední zastávky | N9: Senaste stoppzonstyper | O9: Son Duraklama Alan Türleri | P9: Jenis Zon Hentian Terakhir | Q9: Type de zone du dernier arrêt | R9: 마지막 정지 구역 유형 | S9: 上次停車區域類型
A10: **Current Odometer | B10: Odomètre actuel | C10: Odómetro actual | D10: Derzeitiger Kilometerstand | E10: 現在のオドメーター | F10: Aktualny stan licznika | G10: Hodômetro atual | H10: Huidige kilometerteller | I10: Contachilometri attuale | J10: 当前里程 | K10: มาตรระยะทางปัจจุบัน | L10: Odometer Saat Ini | M10: Aktuální počítadlo ujetých kilometrů | N10: Aktuell mätarställning | O10: Geçerli Kilometre Sayacı | P10: Odometer semasa | Q10: Odomètre actuel | R10: 현재 주행 기록계 | S10: 目前里程表
A11: **Current Engine Hours | B11: Heures de moteur actuelles | C11: Horas del motor actual | D11: Aktuelle Betriebsstunden | E11: 現在のエンジン稼働時間 | F11: Biezace godziny pracy silnika | G11: Horas de motor atuais | H11: Huidige motoruren | I11: Ore motore attuali | J11: 当前发动机运转小时数 | K11: จำนวนชั่วโมงเดินเครื่องปัจจุบัน | L11: Jam Mesin Saat Ini | M11: Aktuální doba chodu motoru | N11: Nuvarande motortimmar | O11: Geçerli Motor Saati | P11: Jam Enjin Beroperasi Semasa | Q11: Heures-moteur actuelles | R11: 현재 엔진 시간 | S11: 目前引擎時數
A12: **Active from | B12: Actif depuis | C12: Activo desde | D12: Aktiv seit | E12: アクティブ開始： | F12: Aktywny od | G12: Ativo desde | H12: Actief van | I12: Attivo da | J12: 激活自 | K12: ใช้งานตั้งแต่ | L12: Aktif dari | M12: Aktivní od | N12: Aktiv från | O12: Bu tarihten itibaren aktif | P12: Aktif dari | Q12: Actif depuis | R12: 활성 시작 | S12: 使用中自
... A31: **Plan | B31: Forfait | C31: Plan | D31: Plan | E31: プラン | F31: Plan | G31: Plano | H31: Plan | I31: Piano | J31: 计划 | K31: แผน | L31: Paket | M31: Plán | N31: Plan | O31: Plan | P31: Pelan | Q31: Forfait | R31: 계획 | S31: 計劃
