Workbook
Name AllData: Report!$A$13:$P$44

Sheet Data
A1: CompanyName | B1: United Civil Construction Limited
A2: RunDate | B2: 45977.707
A3: FromDate | B3: 45976
A4: ToDate | B4: 45977
A5: TimeZone | B5: Pacific/Auckland
A6: DistanceUnit | B6: km
A7: SpeedUnit | B7: km/h
A8: SendReport | B8: =TRUE() -> TRUE
A9: LastModifiedUser | B9: **<No User>
A10: Language | B10: en
A11: .Device.DeviceName | B11: .Device.DeviceId | C11: .Device.DeviceComment | D11: .Device.DeviceGroup | E11: .Device.DeviceGroup|Company Group | F11: .Driver.UserFirstName | G11: .Driver.UserLastName | H11: .Driver.UserName | I11: .Driver.UserId | J11: .Driver.UserComment | K11: .Driver.DriverGroup | L11: .Driver.DriverGroup|Company Group | M11: .ExceptionRule.ExceptionRuleName | N11: ExceptionDetailLongitude | O11: ExceptionDetailLatitude | P11: ExceptionDetailLocation | Q11: Location.ZoneZoneTypes | R11: Location.ZoneExternalReference | S11: ExceptionDetailStartTime | T11: ExceptionDuration | U11: ExceptionDistance | V11: ExceptionDetailExtraInfo | W11: ExceptionDetailDetails | X11: ExceptionStatus
A12: 128 | B12: b170 | C12: 23.5T Hyundai R235LCR-9 2016 | D12: Digger, Diesel, Excavator/Tradestaff, Machines, Trade Staff | E12: Diesel, Digger, Excavator/Tradestaff, Machines, Trade Staff | M12: Idling >10 mins and <100 m | N12: 174.32332 | O12: -35.735592 | P12: Morningside: 65 Morningside Rd, Northland Region 0110, New Zealand | Q12: Project | S12: 45976.331 | T12: 0.016699954 | U12: 0.012914205 | V12: Ignition: 1.00 | W12: Idling >10 mins and <100 m | X12: Valid
A13: 128 | B13: b170 | C13: 23.5T Hyundai R235LCR-9 2016 | D13: Digger, Diesel, Excavator/Tradestaff, Machines, Trade Staff | E13: Diesel, Digger, Excavator/Tradestaff, Machines, Trade Staff | M13: Idling >5 mins and <100 m | N13: 174.32332 | O13: -35.735592 | P13: Morningside: 65 Morningside Rd, Northland Region 0110, New Zealand | Q13: Project | S13: 45976.331 | T13: 0.016699954 | U13: 0.012914205 | V13: Ignition: 1.00 | W13: Idling >5 mins and <100 m | X13: Valid
A14: 128 | B14: b170 | C14: 23.5T Hyundai R235LCR-9 2016 | D14: Digger, Diesel, Excavator/Tradestaff, Machines, Trade Staff | E14: Diesel, Digger, Excavator/Tradestaff, Machines, Trade Staff | F14: Paul | G14: Travers | H14: paul.travers | I14: b113 | K14: Excavator/Tradestaff, Grader/Trade Staff, HDV/Trade Staff, Loader/Trade Staff, Roller/Trade Staff, Telehandler/Trade Staff, Trade Staff | L14: Excavator/Tradestaff, Grader/Trade Staff, HDV/Trade Staff, Loader/Trade Staff, Roller/Trade Staff, Telehandler/Trade Staff, Trade Staff | M14: Idling >10 mins and <100 m | N14: 174.3224 | O14: -35.735683 | P14: Morningside: 74 Morningside Road, Morningside, Whangārei 0110, New Zealand | Q14: Project | S14: 45976.354 | T14: 0.014921933 | U14: 0.02974432 | V14: Ignition: 1.00 | W14: Idling >10 mins and <100 m | X14: Valid
A15: 128 | B15: b170 | C15: 23.5T Hyundai R235LCR-9 2016 | D15: Digger, Diesel, Excavator/Tradestaff, Machines, Trade Staff | E15: Diesel, Digger, Excavator/Tradestaff, Machines, Trade Staff | F15: Paul | G15: Travers | H15: paul.travers | I15: b113 | K15: Excavator/Tradestaff, Grader/Trade Staff, HDV/Trade Staff, Loader/Trade Staff, Roller/Trade Staff, Telehandler/Trade Staff, Trade Staff | L15: Excavator/Tradestaff, Grader/Trade Staff, HDV/Trade Staff, Loader/Trade Staff, Roller/Trade Staff, Telehandler/Trade Staff, Trade Staff | M15: Idling >5 mins and <100 m | N15: 174.3224 | O15: -35.735683 | P15: Morningside: 74 Morningside Road, Morningside, Whangārei 0110, New Zealand | Q15: Project | S15: 45976.354 | T15: 0.014921933 | U15: 0.02974432 | V15: Ignition: 1.00 | W15: Idling >5 mins and <100 m | X15: Valid
A16: 128 | B16: b170 | C16: 23.5T Hyundai R235LCR-9 2016 | D16: Digger, Diesel, Excavator/Tradestaff, Machines, Trade Staff | E16: Diesel, Digger, Excavator/Tradestaff, Machines, Trade Staff | F16: Paul | G16: Travers | H16: paul.travers | I16: b113 | K16: Excavator/Tradestaff, Grader/Trade Staff, HDV/Trade Staff, Loader/Trade Staff, Roller/Trade Staff, Telehandler/Trade Staff, Trade Staff | L16: Excavator/Tradestaff, Grader/Trade Staff, HDV/Trade Staff, Loader/Trade Staff, Roller/Trade Staff, Telehandler/Trade Staff, Trade Staff | M16: Idling >10 mins and <100 m | N16: 174.32242 | O16: -35.735703 | P16: Morningside: 74 Morningside Road, Morningside, Whangārei 0110, New Zealand | Q16: Project | S16: 45976.375 | T16: 0.014943229 | U16: 0.06397517 | V16: Ignition: 1.00 | W16: Idling >10 mins and <100 m | X16: Valid
A17: 128 | B17: b170 | C17: 23.5T Hyundai R235LCR-9 2016 | D17: Digger, Diesel, Excavator/Tradestaff, Machines, Trade Staff | E17: Diesel, Digger, Excavator/Tradestaff, Machines, Trade Staff | F17: Paul | G17: Travers | H17: paul.travers | I17: b113 | K17: Excavator/Tradestaff, Grader/Trade Staff, HDV/Trade Staff, Loader/Trade Staff, Roller/Trade Staff, Telehandler/Trade Staff, Trade Staff | L17: Excavator/Tradestaff, Grader/Trade Staff, HDV/Trade Staff, Loader/Trade Staff, Roller/Trade Staff, Telehandler/Trade Staff, Trade Staff | M17: Idling >5 mins and <100 m | N17: 174.32242 | O17: -35.735703 | P17: Morningside: 74 Morningside Road, Morningside, Whangārei 0110, New Zealand | Q17: Project | S17: 45976.375 | T17: 0.014943229 | U17: 0.06397517 | V17: Ignition: 1.00 | W17: Idling >5 mins and <100 m | X17: Valid
A18: 128 | B18: b170 | C18: 23.5T Hyundai R235LCR-9 2016 | D18: Digger, Diesel, Excavator/Tradestaff, Machines, Trade Staff | E18: Diesel, Digger, Excavator/Tradestaff, Machines, Trade Staff | F18: Paul | G18: Travers | H18: paul.travers | I18: b113 | K18: Excavator/Tradestaff, Grader/Trade Staff, HDV/Trade Staff, Loader/Trade Staff, Roller/Trade Staff, Telehandler/Trade Staff, Trade Staff | L18: Excavator/Tradestaff, Grader/Trade Staff, HDV/Trade Staff, Loader/Trade Staff, Roller/Trade Staff, Telehandler/Trade Staff, Trade Staff | M18: Idling >5 mins and <100 m | N18: 174.3224 | O18: -35.735668 | P18: Morningside: 74 Morningside Road, Morningside, Whangārei 0110, New Zealand | Q18: Project | S18: 45976.392 | T18: 0.0037944213 | U18: 0.014927818 | V18: Ignition: 1.00 | W18: Idling >5 mins and <100 m | X18: Valid
A19: 128 | B19: b170 | C19: 23.5T Hyundai R235LCR-9 2016 | D19: Digger, Diesel, Excavator/Tradestaff, Machines, Trade Staff | E19: Diesel, Digger, Excavator/Tradestaff, Machines, Trade Staff | F19: Paul | G19: Travers | H19: paul.travers | I19: b113 | K19: Excavator/Tradestaff, Grader/Trade Staff, HDV/Trade Staff, Loader/Trade Staff, Roller/Trade Staff, Telehandler/Trade Staff, Trade Staff | L19: Excavator/Tradestaff, Grader/Trade Staff, HDV/Trade Staff, Loader/Trade Staff, Roller/Trade Staff, Telehandler/Trade Staff, Trade Staff | M19: Idling >5 mins and <100 m | N19: 174.3224 | O19: -35.735676 | P19: Morningside: 74 Morningside Road, Morningside, Whangārei 0110, New Zealand | Q19: Project | S19: 45976.468 | T19: 0.0038735417 | U19: 0.092259243 | V19: Ignition: 1.00 | W19: Idling >5 mins and <100 m | X19: Valid
A20: 128 | B20: b170 | C20: 23.5T Hyundai R235LCR-9 2016 | D20: Digger, Diesel, Excavator/Tradestaff, Machines, Trade Staff | E20: Diesel, Digger, Excavator/Tradestaff, Machines, Trade Staff | F20: Paul | G20: Travers | H20: paul.travers | I20: b113 | K20: Excavator/Tradestaff, Grader/Trade Staff, HDV/Trade Staff, Loader/Trade Staff, Roller/Trade Staff, Telehandler/Trade Staff, Trade Staff | L20: Excavator/Tradestaff, Grader/Trade Staff, HDV/Trade Staff, Loader/Trade Staff, Roller/Trade Staff, Telehandler/Trade Staff, Trade Staff | M20: Idling >5 mins and <100 m | N20: 174.32239 | O20: -35.735641 | P20: Morningside: 74 Morningside Road, Morningside, Whangārei 0110, New Zealand | Q20: Project | S20: 45976.483 | T20: 0.0042746528 | U20: 0.024742059 | V20: Ignition: 1.00 | W20: Idling >5 mins and <100 m | X20: Valid
A21: 128 | B21: b170 | C21: 23.5T Hyundai R235LCR-9 2016 | D21: Digger, Diesel, Excavator/Tradestaff, Machines, Trade Staff | E21: Diesel, Digger, Excavator/Tradestaff, Machines, Trade Staff | F21: Paul | G21: Travers | H21: paul.travers | I21: b113 | K21: Excavator/Tradestaff, Grader/Trade Staff, HDV/Trade Staff, Loader/Trade Staff, Roller/Trade Staff, Telehandler/Trade Staff, Trade Staff | L21: Excavator/Tradestaff, Grader/Trade Staff, HDV/Trade Staff, Loader/Trade Staff, Roller/Trade Staff, Telehandler/Trade Staff, Trade Staff | M21: Idling >5 mins and <100 m | N21: 174.3224 | O21: -35.73568 | P21: Morningside: 74 Morningside Road, Morningside, Whangārei 0110, New Zealand | Q21: Project | S21: 45976.488 | T21: 0.018453368 | U21: 0.042736147 | V21: Ignition: 1.00 | W21: Idling >5 mins and <100 m | X21: Valid
A22: 128 | B22: b170 | C22: 23.5T Hyundai R235LCR-9 2016 | D22: Digger, Diesel, Excavator/Tradestaff, Machines, Trade Staff | E22: Diesel, Digger, Excavator/Tradestaff, Machines, Trade Staff | F22: Paul | G22: Travers | H22: paul.travers | I22: b113 | K22: Excavator/Tradestaff, Grader/Trade Staff, HDV/Trade Staff, Loader/Trade Staff, Roller/Trade Staff, Telehandler/Trade Staff, Trade Staff | L22: Excavator/Tradestaff, Grader/Trade Staff, HDV/Trade Staff, Loader/Trade Staff, Roller/Trade Staff, Telehandler/Trade Staff, Trade Staff | M22: Idling >10 mins and <100 m | N22: 174.3224 | O22: -35.73568 | P22: Morningside: 74 Morningside Road, Morningside, Whangārei 0110, New Zealand | Q22: Project | S22: 45976.488 | T22: 0.018453368 | U22: 0.042736147 | V22: Ignition: 1.00 | W22: Idling >10 mins and <100 m | X22: Valid
A23: 141 | B23: b175 | C23: 6T Hitachi ZX65USB-5A 2022 | D23: Digger, Excavator/Tradestaff, Machines, Trade Staff | E23: Digger, Excavator/Tradestaff, Machines, Trade Staff | M23: Idling >5 mins and <100 m | N23: 174.32271 | O23: -35.735783 | P23: Morningside: 80 Morningside Road, Morningside, Whangārei 0110, New Zealand | Q23: Project | S23: 45976.342 | T23: 0.067446319 | U23: 0 | V23: Ignition: 1.00 | W23: Idling >5 mins and <100 m | X23: Valid
A24: 141 | B24: b175 | C24: 6T Hitachi ZX65USB-5A 2022 | D24: Digger, Excavator/Tradestaff, Machines, Trade Staff | E24: Digger, Excavator/Tradestaff, Machines, Trade Staff | M24: Idling >10 mins and <100 m | N24: 174.32271 | O24: -35.735783 | P24: Morningside: 80 Morningside Road, Morningside, Whangārei 0110, New Zealand | Q24: Project | S24: 45976.342 | T24: 0.067446319 | U24: 0 | V24: Ignition: 1.00 | W24: Idling >10 mins and <100 m | X24: Valid
A25: 141 | B25: b175 | C25: 6T Hitachi ZX65USB-5A 2022 | D25: Digger, Excavator/Tradestaff, Machines, Trade Staff | E25: Digger, Excavator/Tradestaff, Machines, Trade Staff | M25: Idling >5 mins and <100 m | N25: 174.32271 | O25: -35.735783 | P25: Morningside: 80 Morningside Road, Morningside, Whangārei 0110, New Zealand | Q25: Project | S25: 45976.496 | T25: 0.0038476273 | U25: 0 | V25: Ignition: 1.00 | W25: Idling >5 mins and <100 m | X25: Valid
A26: 141 | B26: b175 | C26: 6T Hitachi ZX65USB-5A 2022 | D26: Digger, Excavator/Tradestaff, Machines, Trade Staff | E26: Digger, Excavator/Tradestaff, Machines, Trade Staff | M26: Idling >5 mins and <100 m | N26: 174.32271 | O26: -35.735783 | P26: Morningside: 80 Morningside Road, Morningside, Whangārei 0110, New Zealand | Q26: Project | S26: 45976.538 | T26: 0.028308148 | U26: 0 | V26: Ignition: 1.00 | W26: Idling >5 mins and <100 m | X26: Valid
A27: 141 | B27: b175 | C27: 6T Hitachi ZX65USB-5A 2022 | D27: Digger, Excavator/Tradestaff, Machines, Trade Staff | E27: Digger, Excavator/Tradestaff, Machines, Trade Staff | M27: Idling >10 mins and <100 m | N27: 174.32271 | O27: -35.735783 | P27: Morningside: 80 Morningside Road, Morningside, Whangārei 0110, New Zealand | Q27: Project | S27: 45976.538 | T27: 0.028308148 | U27: 0 | V27: Ignition: 1.00 | W27: Idling >10 mins and <100 m | X27: Valid
A28: 141 | B28: b175 | C28: 6T Hitachi ZX65USB-5A 2022 | D28: Digger, Excavator/Tradestaff, Machines, Trade Staff | E28: Digger, Excavator/Tradestaff, Machines, Trade Staff | M28: Idling >5 mins and <100 m | N28: 174.32271 | O28: -35.735783 | P28: Morningside: 80 Morningside Road, Morningside, Whangārei 0110, New Zealand | Q28: Project | S28: 45976.572 | T28: 0.030982176 | U28: 0 | V28: Ignition: 1.00 | W28: Idling >5 mins and <100 m | X28: Valid
A29: 141 | B29: b175 | C29: 6T Hitachi ZX65USB-5A 2022 | D29: Digger, Excavator/Tradestaff, Machines, Trade Staff | E29: Digger, Excavator/Tradestaff, Machines, Trade Staff | M29: Idling >10 mins and <100 m | N29: 174.32271 | O29: -35.735783 | P29: Morningside: 80 Morningside Road, Morningside, Whangārei 0110, New Zealand | Q29: Project | S29: 45976.572 | T29: 0.030982176 | U29: 0 | V29: Ignition: 1.00 | W29: Idling >10 mins and <100 m | X29: Valid
A30: 141 | B30: b175 | C30: 6T Hitachi ZX65USB-5A 2022 | D30: Digger, Excavator/Tradestaff, Machines, Trade Staff | E30: Digger, Excavator/Tradestaff, Machines, Trade Staff | M30: Idling >5 mins and <100 m | N30: 174.32271 | O30: -35.735783 | P30: Morningside: 80 Morningside Road, Morningside, Whangārei 0110, New Zealand | Q30: Project | S30: 45976.603 | T30: 0.0084594792 | U30: 0 | V30: Ignition: 1.00 | W30: Idling >5 mins and <100 m | X30: Valid
A31: 141 | B31: b175 | C31: 6T Hitachi ZX65USB-5A 2022 | D31: Digger, Excavator/Tradestaff, Machines, Trade Staff | E31: Digger, Excavator/Tradestaff, Machines, Trade Staff | M31: Idling >10 mins and <100 m | N31: 174.32271 | O31: -35.735783 | P31: Morningside: 80 Morningside Road, Morningside, Whangārei 0110, New Zealand | Q31: Project | S31: 45976.603 | T31: 0.0084594792 | U31: 0 | V31: Ignition: 1.00 | W31: Idling >10 mins and <100 m | X31: Valid
A32: 141 | B32: b175 | C32: 6T Hitachi ZX65USB-5A 2022 | D32: Digger, Excavator/Tradestaff, Machines, Trade Staff | E32: Digger, Excavator/Tradestaff, Machines, Trade Staff | M32: Idling >5 mins and <100 m | N32: 174.32271 | O32: -35.735783 | P32: Morningside: 80 Morningside Road, Morningside, Whangārei 0110, New Zealand | Q32: Project | S32: 45976.626 | T32: 0.039965949 | U32: 0 | V32: Ignition: 1.00 | W32: Idling >5 mins and <100 m | X32: Valid
A33: 141 | B33: b175 | C33: 6T Hitachi ZX65USB-5A 2022 | D33: Digger, Excavator/Tradestaff, Machines, Trade Staff | E33: Digger, Excavator/Tradestaff, Machines, Trade Staff | M33: Idling >10 mins and <100 m | N33: 174.32271 | O33: -35.735783 | P33: Morningside: 80 Morningside Road, Morningside, Whangārei 0110, New Zealand | Q33: Project | S33: 45976.626 | T33: 0.039965949 | U33: 0 | V33: Ignition: 1.00 | W33: Idling >10 mins and <100 m | X33: Valid
A34: 3414 | B34: b18F | C34: Mitsubishi Fuso Fighter FK200K6 2007 | D34: Heavy Diesel Vehicles, HDV/Trade Staff, Machines, Trade Staff | E34: HDV/Trade Staff, Heavy Diesel Vehicles, Machines, Trade Staff | M34: Idling >5 mins and <100 m | N34: 174.44339 | O34: -35.870369 | P34: Ruakaka Solar Farm Site 2: 41 Mccathie Road, Ruakākā 0171, New Zealand | Q34: Project | S34: 45976.299 | T34: 0.0050154282 | U34: 0.097542405 | V34: Ignition: 1.00 | W34: Idling >5 mins and <100 m | X34: Valid
A35: 519 | B35: bB2 | C35: Ford Ranger 2021 4x2 XLT D/C W/S | D35: Light Diesel Vehicles, Diesel, LDV/PM, PM | E35: Diesel, LDV/PM, Light Diesel Vehicles, PM | F35: Wayne | G35: Pepperell | H35: wayne.pepperell@unitedcivil.co.nz | I35: bDD | K35: LDV/PM, PM | L35: LDV/PM, PM | M35: Idling >5 mins and <100 m | N35: 174.28593 | O35: -35.69397 | P35: 26 Angus Lane, Te Kamo, Whangārei 0112, New Zealand | S35: 45976.58 | T35: 0.0035314236 | U35: 0.054281525 | V35: Ignition: 1.00 | W35: Idling >5 mins and <100 m | X35: Valid
A36: 536 | B36: bF3 | C36: Tesla Model Y 2023 | D36: Electric Vehicles, Battery Electric Vehicle, EV/Other Management, Other Management | E36: Battery Electric Vehicle, Electric Vehicles, EV/Other Management, Other Management | F36: Tony | G36: Abiad | H36: tony.abiad@unitedcivil.co.nz | I36: b152 | K36: EV/Other Management, Other Management | L36: EV/Other Management, Other Management | M36: Idling >5 mins and <100 m | N36: 176.83174 | O36: -39.621639 | P36: 510 Hart Drive, Frimley, Hastings 4120, New Zealand | S36: 45976.387 | T36: 0.013786701 | U36: 0 | V36: Ignition: 1.00 | W36: Idling >5 mins and <100 m | X36: Valid
A37: 536 | B37: bF3 | C37: Tesla Model Y 2023 | D37: Electric Vehicles, Battery Electric Vehicle, EV/Other Management, Other Management | E37: Battery Electric Vehicle, Electric Vehicles, EV/Other Management, Other Management | F37: Tony | G37: Abiad | H37: tony.abiad@unitedcivil.co.nz | I37: b152 | K37: EV/Other Management, Other Management | L37: EV/Other Management, Other Management | M37: Idling >10 mins and <100 m | N37: 176.83174 | O37: -39.621639 | P37: 510 Hart Drive, Frimley, Hastings 4120, New Zealand | S37: 45976.387 | T37: 0.013786701 | U37: 0 | V37: Ignition: 1.00 | W37: Idling >10 mins and <100 m | X37: Valid
A38: 536 | B38: bF3 | C38: Tesla Model Y 2023 | D38: Electric Vehicles, Battery Electric Vehicle, EV/Other Management, Other Management | E38: Battery Electric Vehicle, Electric Vehicles, EV/Other Management, Other Management | F38: Tony | G38: Abiad | H38: tony.abiad@unitedcivil.co.nz | I38: b152 | K38: EV/Other Management, Other Management | L38: EV/Other Management, Other Management | M38: Idling >10 mins and <100 m | N38: 176.83174 | O38: -39.621639 | P38: 510 Hart Drive, Frimley, Hastings 4120, New Zealand | S38: 45976.686 | T38: 0.012358391 | U38: 0 | V38: Ignition: 1.00 | W38: Idling >10 mins and <100 m | X38: Valid
A39: 536 | B39: bF3 | C39: Tesla Model Y 2023 | D39: Electric Vehicles, Battery Electric Vehicle, EV/Other Management, Other Management | E39: Battery Electric Vehicle, Electric Vehicles, EV/Other Management, Other Management | F39: Tony | G39: Abiad | H39: tony.abiad@unitedcivil.co.nz | I39: b152 | K39: EV/Other Management, Other Management | L39: EV/Other Management, Other Management | M39: Idling >5 mins and <100 m | N39: 176.83174 | O39: -39.621639 | P39: 510 Hart Drive, Frimley, Hastings 4120, New Zealand | S39: 45976.686 | T39: 0.012358391 | U39: 0 | V39: Ignition: 1.00 | W39: Idling >5 mins and <100 m | X39: Valid
A40: 536 | B40: bF3 | C40: Tesla Model Y 2023 | D40: Electric Vehicles, Battery Electric Vehicle, EV/Other Management, Other Management | E40: Battery Electric Vehicle, Electric Vehicles, EV/Other Management, Other Management | F40: Tony | G40: Abiad | H40: tony.abiad@unitedcivil.co.nz | I40: b152 | K40: EV/Other Management, Other Management | L40: EV/Other Management, Other Management | M40: Idling >5 mins and <100 m | N40: 176.83174 | O40: -39.621639 | P40: 510 Hart Drive, Frimley, Hastings 4120, New Zealand | S40: 45976.725 | T40: 0.0069187037 | U40: 0 | V40: Ignition: 1.00 | W40: Idling >5 mins and <100 m | X40: Valid
...

Sheet Report
A1: Exceptions Detail Report | C1: =Data!B2 -> 45977.707
A2: =Data!B1 -> United Civil Construction Limited
A4: Date
A5: From | B5: =Data!B3 -> 45976
A6: To | B6: =Data!B4 -> 45977
A7: Days | B7: =B6-B5 -> 0.99998843
A9: Time Zone | B9: =Data!B5 -> Pacific/Auckland
A10: Distance Unit | B10: =Data!B6 -> km
A11: Speed Unit | B11: =Data!B7 -> km/h
A13: Device | B13: Device Group | C13: First Name | D13: Last Name | E13: Driver | F13: Driver Group | G13: Rule | H13: Location | I13: Location Zone Types | J13: Date | K13: Start Time | L13: Duration | M13: Distance | N13: Extra Info | O13: Details | P13: Status
A14: =Data!A12 -> 128 | B14: =Data!D12 -> Digger, Diesel, Excavator/Tradestaff, Machines, Trade Staff | C14: =Data!F12 -> 0 | D14: =Data!G12 -> 0 | E14: =Data!H12 -> 0 | F14: =Data!K12 -> 0 | G14: =Data!M12 -> Idling >10 mins and <100 m | H14: =Data!P12 -> Morningside: 65 Morningside Rd, Northland Region 0110, New Zealand | I14: =Data!Q12 -> Project | J14: =Data!S12 -> 45976.331 | K14: =Data!S12 -> 45976.331 | L14: =Data!T12 -> 0.016699954 | M14: =Data!U12 -> 0.012914205 | N14: =CONCATENATE(Data!W12," (",Data!V12,")") -> Idling >10 mins and <100 m (Ignition: 1.00) | O14: =IF(Data!V12<>"",N14,Data!W12) -> Idling >10 mins and <100 m (Ignition: 1.00) | P14: =Data!X12 -> Valid
A15: =Data!A13 -> 128 | B15: =Data!D13 -> Digger, Diesel, Excavator/Tradestaff, Machines, Trade Staff | C15: =Data!F13 -> 0 | D15: =Data!G13 -> 0 | E15: =Data!H13 -> 0 | F15: =Data!K13 -> 0 | G15: =Data!M13 -> Idling >5 mins and <100 m | H15: =Data!P13 -> Morningside: 65 Morningside Rd, Northland Region 0110, New Zealand | I15: =Data!Q13 -> Project | J15: =Data!S13 -> 45976.331 | K15: =Data!S13 -> 45976.331 | L15: =Data!T13 -> 0.016699954 | M15: =Data!U13 -> 0.012914205 | N15: =CONCATENATE(Data!W13," (",Data!V13,")") -> Idling >5 mins and <100 m (Ignition: 1.00) | O15: =IF(Data!V13<>"",N15,Data!W13) -> Idling >5 mins and <100 m (Ignition: 1.00) | P15: =Data!X13 -> Valid
A16: =Data!A14 -> 128 | B16: =Data!D14 -> Digger, Diesel, Excavator/Tradestaff, Machines, Trade Staff | C16: =Data!F14 -> Paul | D16: =Data!G14 -> Travers | E16: =Data!H14 -> paul.travers | F16: =Data!K14 -> Excavator/Tradestaff, Grader/Trade Staff, HDV/Trade Staff, Loader/Trade Staff, Roller/Trade Staff, Telehandler/Trade Staff, Trade Staff | G16: =Data!M14 -> Idling >10 mins and <100 m | H16: =Data!P14 -> Morningside: 74 Morningside Road, Morningside, Whangārei 0110, New Zealand | I16: =Data!Q14 -> Project | J16: =Data!S14 -> 45976.354 | K16: =Data!S14 -> 45976.354 | L16: =Data!T14 -> 0.014921933 | M16: =Data!U14 -> 0.02974432 | N16: =CONCATENATE(Data!W14," (",Data!V14,")") -> Idling >10 mins and <100 m (Ignition: 1.00) | O16: =IF(Data!V14<>"",N16,Data!W14) -> Idling >10 mins and <100 m (Ignition: 1.00) | P16: =Data!X14 -> Valid
A17: =Data!A15 -> 128 | B17: =Data!D15 -> Digger, Diesel, Excavator/Tradestaff, Machines, Trade Staff | C17: =Data!F15 -> Paul | D17: =Data!G15 -> Travers | E17: =Data!H15 -> paul.travers | F17: =Data!K15 -> Excavator/Tradestaff, Grader/Trade Staff, HDV/Trade Staff, Loader/Trade Staff, Roller/Trade Staff, Telehandler/Trade Staff, Trade Staff | G17: =Data!M15 -> Idling >5 mins and <100 m | H17: =Data!P15 -> Morningside: 74 Morningside Road, Morningside, Whangārei 0110, New Zealand | I17: =Data!Q15 -> Project | J17: =Data!S15 -> 45976.354 | K17: =Data!S15 -> 45976.354 | L17: =Data!T15 -> 0.014921933 | M17: =Data!U15 -> 0.02974432 | N17: =CONCATENATE(Data!W15," (",Data!V15,")") -> Idling >5 mins and <100 m (Ignition: 1.00) | O17: =IF(Data!V15<>"",N17,Data!W15) -> Idling >5 mins and <100 m (Ignition: 1.00) | P17: =Data!X15 -> Valid
A18: =Data!A16 -> 128 | B18: =Data!D16 -> Digger, Diesel, Excavator/Tradestaff, Machines, Trade Staff | C18: =Data!F16 -> Paul | D18: =Data!G16 -> Travers | E18: =Data!H16 -> paul.travers | F18: =Data!K16 -> Excavator/Tradestaff, Grader/Trade Staff, HDV/Trade Staff, Loader/Trade Staff, Roller/Trade Staff, Telehandler/Trade Staff, Trade Staff | G18: =Data!M16 -> Idling >10 mins and <100 m | H18: =Data!P16 -> Morningside: 74 Morningside Road, Morningside, Whangārei 0110, New Zealand | I18: =Data!Q16 -> Project | J18: =Data!S16 -> 45976.375 | K18: =Data!S16 -> 45976.375 | L18: =Data!T16 -> 0.014943229 | M18: =Data!U16 -> 0.06397517 | N18: =CONCATENATE(Data!W16," (",Data!V16,")") -> Idling >10 mins and <100 m (Ignition: 1.00) | O18: =IF(Data!V16<>"",N18,Data!W16) -> Idling >10 mins and <100 m (Ignition: 1.00) | P18: =Data!X16 -> Valid
A19: =Data!A17 -> 128 | B19: =Data!D17 -> Digger, Diesel, Excavator/Tradestaff, Machines, Trade Staff | C19: =Data!F17 -> Paul | D19: =Data!G17 -> Travers | E19: =Data!H17 -> paul.travers | F19: =Data!K17 -> Excavator/Tradestaff, Grader/Trade Staff, HDV/Trade Staff, Loader/Trade Staff, Roller/Trade Staff, Telehandler/Trade Staff, Trade Staff | G19: =Data!M17 -> Idling >5 mins and <100 m | H19: =Data!P17 -> Morningside: 74 Morningside Road, Morningside, Whangārei 0110, New Zealand | I19: =Data!Q17 -> Project | J19: =Data!S17 -> 45976.375 | K19: =Data!S17 -> 45976.375 | L19: =Data!T17 -> 0.014943229 | M19: =Data!U17 -> 0.06397517 | N19: =CONCATENATE(Data!W17," (",Data!V17,")") -> Idling >5 mins and <100 m (Ignition: 1.00) | O19: =IF(Data!V17<>"",N19,Data!W17) -> Idling >5 mins and <100 m (Ignition: 1.00) | P19: =Data!X17 -> Valid
A20: =Data!A18 -> 128 | B20: =Data!D18 -> Digger, Diesel, Excavator/Tradestaff, Machines, Trade Staff | C20: =Data!F18 -> Paul | D20: =Data!G18 -> Travers | E20: =Data!H18 -> paul.travers | F20: =Data!K18 -> Excavator/Tradestaff, Grader/Trade Staff, HDV/Trade Staff, Loader/Trade Staff, Roller/Trade Staff, Telehandler/Trade Staff, Trade Staff | G20: =Data!M18 -> Idling >5 mins and <100 m | H20: =Data!P18 -> Morningside: 74 Morningside Road, Morningside, Whangārei 0110, New Zealand | I20: =Data!Q18 -> Project | J20: =Data!S18 -> 45976.392 | K20: =Data!S18 -> 45976.392 | L20: =Data!T18 -> 0.0037944213 | M20: =Data!U18 -> 0.014927818 | N20: =CONCATENATE(Data!W18," (",Data!V18,")") -> Idling >5 mins and <100 m (Ignition: 1.00) | O20: =IF(Data!V18<>"",N20,Data!W18) -> Idling >5 mins and <100 m (Ignition: 1.00) | P20: =Data!X18 -> Valid
A21: =Data!A19 -> 128 | B21: =Data!D19 -> Digger, Diesel, Excavator/Tradestaff, Machines, Trade Staff | C21: =Data!F19 -> Paul | D21: =Data!G19 -> Travers | E21: =Data!H19 -> paul.travers | F21: =Data!K19 -> Excavator/Tradestaff, Grader/Trade Staff, HDV/Trade Staff, Loader/Trade Staff, Roller/Trade Staff, Telehandler/Trade Staff, Trade Staff | G21: =Data!M19 -> Idling >5 mins and <100 m | H21: =Data!P19 -> Morningside: 74 Morningside Road, Morningside, Whangārei 0110, New Zealand | I21: =Data!Q19 -> Project | J21: =Data!S19 -> 45976.468 | K21: =Data!S19 -> 45976.468 | L21: =Data!T19 -> 0.0038735417 | M21: =Data!U19 -> 0.092259243 | N21: =CONCATENATE(Data!W19," (",Data!V19,")") -> Idling >5 mins and <100 m (Ignition: 1.00) | O21: =IF(Data!V19<>"",N21,Data!W19) -> Idling >5 mins and <100 m (Ignition: 1.00) | P21: =Data!X19 -> Valid
A22: =Data!A20 -> 128 | B22: =Data!D20 -> Digger, Diesel, Excavator/Tradestaff, Machines, Trade Staff | C22: =Data!F20 -> Paul | D22: =Data!G20 -> Travers | E22: =Data!H20 -> paul.travers | F22: =Data!K20 -> Excavator/Tradestaff, Grader/Trade Staff, HDV/Trade Staff, Loader/Trade Staff, Roller/Trade Staff, Telehandler/Trade Staff, Trade Staff | G22: =Data!M20 -> Idling >5 mins and <100 m | H22: =Data!P20 -> Morningside: 74 Morningside Road, Morningside, Whangārei 0110, New Zealand | I22: =Data!Q20 -> Project | J22: =Data!S20 -> 45976.483 | K22: =Data!S20 -> 45976.483 | L22: =Data!T20 -> 0.0042746528 | M22: =Data!U20 -> 0.024742059 | N22: =CONCATENATE(Data!W20," (",Data!V20,")") -> Idling >5 mins and <100 m (Ignition: 1.00) | O22: =IF(Data!V20<>"",N22,Data!W20) -> Idling >5 mins and <100 m (Ignition: 1.00) | P22: =Data!X20 -> Valid
A23: =Data!A21 -> 128 | B23: =Data!D21 -> Digger, Diesel, Excavator/Tradestaff, Machines, Trade Staff | C23: =Data!F21 -> Paul | D23: =Data!G21 -> Travers | E23: =Data!H21 -> paul.travers | F23: =Data!K21 -> Excavator/Tradestaff, Grader/Trade Staff, HDV/Trade Staff, Loader/Trade Staff, Roller/Trade Staff, Telehandler/Trade Staff, Trade Staff | G23: =Data!M21 -> Idling >5 mins and <100 m | H23: =Data!P21 -> Morningside: 74 Morningside Road, Morningside, Whangārei 0110, New Zealand | I23: =Data!Q21 -> Project | J23: =Data!S21 -> 45976.488 | K23: =Data!S21 -> 45976.488 | L23: =Data!T21 -> 0.018453368 | M23: =Data!U21 -> 0.042736147 | N23: =CONCATENATE(Data!W21," (",Data!V21,")") -> Idling >5 mins and <100 m (Ignition: 1.00) | O23: =IF(Data!V21<>"",N23,Data!W21) -> Idling >5 mins and <100 m (Ignition: 1.00) | P23: =Data!X21 -> Valid
A24: =Data!A22 -> 128 | B24: =Data!D22 -> Digger, Diesel, Excavator/Tradestaff, Machines, Trade Staff | C24: =Data!F22 -> Paul | D24: =Data!G22 -> Travers | E24: =Data!H22 -> paul.travers | F24: =Data!K22 -> Excavator/Tradestaff, Grader/Trade Staff, HDV/Trade Staff, Loader/Trade Staff, Roller/Trade Staff, Telehandler/Trade Staff, Trade Staff | G24: =Data!M22 -> Idling >10 mins and <100 m | H24: =Data!P22 -> Morningside: 74 Morningside Road, Morningside, Whangārei 0110, New Zealand | I24: =Data!Q22 -> Project | J24: =Data!S22 -> 45976.488 | K24: =Data!S22 -> 45976.488 | L24: =Data!T22 -> 0.018453368 | M24: =Data!U22 -> 0.042736147 | N24: =CONCATENATE(Data!W22," (",Data!V22,")") -> Idling >10 mins and <100 m (Ignition: 1.00) | O24: =IF(Data!V22<>"",N24,Data!W22) -> Idling >10 mins and <100 m (Ignition: 1.00) | P24: =Data!X22 -> Valid
A25: =Data!A23 -> 141 | B25: =Data!D23 -> Digger, Excavator/Tradestaff, Machines, Trade Staff | C25: =Data!F23 -> 0 | D25: =Data!G23 -> 0 | E25: =Data!H23 -> 0 | F25: =Data!K23 -> 0 | G25: =Data!M23 -> Idling >5 mins and <100 m | H25: =Data!P23 -> Morningside: 80 Morningside Road, Morningside, Whangārei 0110, New Zealand | I25: =Data!Q23 -> Project | J25: =Data!S23 -> 45976.342 | K25: =Data!S23 -> 45976.342 | L25: =Data!T23 -> 0.067446319 | M25: =Data!U23 -> 0 | N25: =CONCATENATE(Data!W23," (",Data!V23,")") -> Idling >5 mins and <100 m (Ignition: 1.00) | O25: =IF(Data!V23<>"",N25,Data!W23) -> Idling >5 mins and <100 m (Ignition: 1.00) | P25: =Data!X23 -> Valid
... A44: =Data!A42 -> 536 | B44: =Data!D42 -> Electric Vehicles, Battery Electric Vehicle, EV/Other Management, Other Management | C44: =Data!F42 -> Tony | D44: =Data!G42 -> Abiad | E44: =Data!H42 -> tony.abiad@unitedcivil.co.nz | F44: =Data!K42 -> EV/Other Management, Other Management | G44: =Data!M42 -> Idling >10 mins and <100 m | H44: =Data!P42 -> 510 Hart Drive, Frimley, Hastings 4120, New Zealand | I44: =Data!Q42 -> 0 | J44: =Data!S42 -> 45976.854 | K44: =Data!S42 -> 45976.854 | L44: =Data!T42 -> 0.012171146 | M44: =Data!U42 -> 0 | N44: =CONCATENATE(Data!W42," (",Data!V42,")") -> Idling >10 mins and <100 m (Ignition: 1.00) | O44: =IF(Data!V42<>"",N44,Data!W42) -> Idling >10 mins and <100 m (Ignition: 1.00) | P44: =Data!X42 -> Valid

Sheet Summary
A1: Exceptions Detail Report | C1: =Data!B2 -> 45977.707
A2: =Data!B1 -> United Civil Construction Limited
A4: Date
A5: From | B5: =Data!B3 -> 45976
A6: To | B6: =Data!B4 -> 45977
A7: Days | B7: =B6-B5 -> 0.99998843
A9: Time Zone | B9: =Data!B5 -> Pacific/Auckland
A10: Distance Unit | B10: =Data!B6 -> km
A11: Speed Unit | B11: =Data!B7 -> km/h
G13: Values
A14: Device | B14: First Name | C14: Last Name | D14: Driver | E14: Rule | F14: Details | G14: Distance | H14: Duration
A15: 128 | B15: 0 | C15: 0 | D15: 0 | E15: Idling >10 mins and <100 m | F15: Idling >10 mins and <100 m (Ignition: 1.00) | G15: 0.012914205 | H15: 0.016701389
E16: Idling >5 mins and <100 m | F16: Idling >5 mins and <100 m (Ignition: 1.00) | G16: 0.012914205 | H16: 0.016701389
B17: Paul | C17: Travers | D17: paul.travers | E17: Idling >10 mins and <100 m | F17: Idling >10 mins and <100 m (Ignition: 1.00) | G17: 0.13645564 | H17: 0.048310185
E18: Idling >5 mins and <100 m | F18: Idling >5 mins and <100 m (Ignition: 1.00) | G18: 0.26838476 | H18: 0.06025463
A19: 141 | B19: 0 | C19: 0 | D19: 0 | E19: Idling >10 mins and <100 m | F19: Idling >10 mins and <100 m (Ignition: 1.00) | G19: 0 | H19: 0.17516204
E20: Idling >5 mins and <100 m | F20: Idling >5 mins and <100 m (Ignition: 1.00) | G20: 0 | H20: 0.17900463
A21: 3414 | B21: 0 | C21: 0 | D21: 0 | E21: Idling >5 mins and <100 m | F21: Idling >5 mins and <100 m (Ignition: 1.00) | G21: 0.097542405 | H21: 0.0050115741
A22: 519 | B22: Wayne | C22: Pepperell | D22: wayne.pepperell@unitedcivil.co.nz | E22: Idling >5 mins and <100 m | F22: Idling >5 mins and <100 m (Ignition: 1.00) | G22: 0.054281525 | H22: 0.0035300926
A23: 536 | B23: Tony | C23: Abiad | D23: tony.abiad@unitedcivil.co.nz | E23: Idling >10 mins and <100 m | F23: Idling >10 mins and <100 m (Ignition: 1.00) | G23: 0 | H23: 0.038321759
E24: Idling >5 mins and <100 m | F24: Idling >5 mins and <100 m (Ignition: 1.00) | G24: 0 | H24: 0.045243056
A25: Grand Total | G25: 0.58249273 | H25: 0.58824074

Sheet Languages
A1: English | B1: French Canada | C1: Spanish | D1: German | E1: Japanese | F1: Polish | G1: Portuguese-Brazil | H1: Dutch | I1: Italian | J1: Simplified Chinese | K1: Thai | L1: Indonesian | M1: Czech | N1: Swedish | O1: Turkish | P1: Malay | Q1: French France | R1: Korean | S1: Traditional Chinese | T1: Danish | U1: Finnish | V1: Hungarian | W1: Norwegian | X1: Slovak
A2: **Device | B2: Dispositif | C2: Dispositivo | D2: Gerät | E2: デバイス | F2: Urzadzenie | G2: Dispositivo | H2: Apparaat | I2: Dispositivo | J2: 设备 | K2: อุปกรณ์ | L2: Perangkat | M2: Zařízení | N2: Enhet | O2: Aygıt | P2: Peranti | Q2: Boîtier | R2: 장치 | S2: 裝置 | T2: Enhed | U2: Laite | V2: Készülék | W2: Enhet | X2: Zariadenie
A3: **First Name | B3: Prénom | C3: Nombre | D3: Vorname | E3: ファーストネー | F3: Imie | G3: Nome | H3: Voornaam | I3: Nome | J3: 名字 | K3: ชื่อ | L3: Nama Depan | M3: Křestní jméno | N3: Förnamn | O3: Ad | P3: Nama pertama | Q3: Prénom | R3: 이름 | S3: 名字 | T3: Fornavn | U3: Etunimi | V3: Keresztnév | W3: Fornavn | X3: Krstné meno
A4: **Last Name | B4: Nom de famille | C4: Apellido | D4: Nachname | E4: ラストネーム | F4: Nazwisko | G4: Sobrenome | H4: Achternaam | I4: Cognome | J4: 姓氏 | K4: นามสกุล | L4: Nama belakang | M4: Příjmení | N4: Efternamn | O4: Soyadı | P4: Nama keluarga | Q4: Nom de famille | R4: 성 | S4: 姓氏 | T4: Efternavn | U4: Sukunimi | V4: Vezetéknév | W4: Etternavn | X4: Priezvisko
A5: **Device Group | B5: Groupe de dispositifs | C5: Grupo de dispositivos | D5: Gerätegruppe | E5: デバイスグループ | F5: Grupa urzadzen | G5: Grupo de dispositivo | H5: Apparaatgroep | I5: Gruppo di dispositivi | J5: 设备的组名 | K5: กลุ่มอุปกรณ์ | L5: Grup Perangkat | M5: Skupina zařízení | N5: Enhetsgrupp | O5: Aygıt Grubu | P5: Kumpulan Peranti | Q5: Groupe de boîtiers | R5: 장치 그룹 | S5: 裝置群組 | T5: Enhedsgruppe | U5: Laiteryhmä | V5: Készülékcsoport | W5: Enhetsgruppe | X5: Skupina zariadení
A6: **Driver | B6: Conducteur | C6: Conductor | D6: Fahrer | E6: ドライバー | F6: Kierowca | G6: Motorista | H6: Chauffeur | I6: Conducente | J6: 驾驶员 | K6: ผู้ขับ | L6: Pengemudi | M6: Řidič | N6: Förare | O6: Sürücü | P6: Pemandu | Q6: Conducteur | R6: 운전자 | S6: 駕駛 | T6: Fører | U6: Kuljettaja | V6: Vezető | W6: Fører | X6: Vodič
A7: **Driver Group | B7: Groupe de chauffeurs | C7: Grupo de conductores | D7: Fahrergruppe | E7: ドライバーグループ | F7: Grupa kierowców | G7: Grupo de motorista | H7: Chauffeursgroep | I7: Gruppo di conducenti | J7: 驾驶员组 | K7: กลุ่มผู้ขับ | L7: Grup Pengemudi | M7: Skupina řidičů | N7: Förargrupp | O7: Sürücü Grubu | P7: Kumpulan Pemandu | Q7: Groupe de conducteurs | R7: 운전자 그룹 | S7: 駕駛群組 | T7: Førergruppe | U7: Kuljettajaryhmä | V7: Vezetőcsoport | W7: Førergruppe | X7: Skupina vodičov
A8: **Rule | B8: Règle | C8: Regla | D8: Regel | E8: ルール | F8: Regula | G8: Regra | H8: Regel | I8: Regola | J8: 规则 | K8: กฎ | L8: Aturan | M8: Pravidlo | N8: Regel | O8: Kural | P8: Peraturan | Q8: Règle | R8: 규칙 | S8: 規則 | T8: Regel | U8: Sääntö | V8: Szabály | W8: Regel | X8: Pravidlo
A9: **Location | B9: Emplacement | C9: Ubicación | D9: Ort | E9: 位置 | F9: Lokalizacja | G9: Localização | H9: Locatie | I9: Ubicazione | J9: 位置 | K9: ตำแหน่งที่ตั้ง | L9: Lokasi | M9: Poloha | N9: Plats | O9: Konum | P9: Lokasi | Q9: Emplacement | R9: 위치 | S9: 位置 | T9: Placering | U9: Sijainti | V9: Hely | W9: Plassering | X9: Poloha
A10: **Location Zone Types | B10: Types de zones de localisation | C10: Tipos de zonas de la ubicación | D10: Standortzonentyp | E10: 場所ゾーンタイプ | F10: Typy stref lokalizacji | G10: Tipos de zona de localização | H10: Types locatiezone | I10: Tipi di zone delle ubicazioni | J10: 位置区域类型 | K10: ประเภทโซนของตำแหน่งที่ตั้ง | L10: Location Zone Types | M10: Typy zón polohy | N10: Platszontyper | O10: Konum Alan Türleri | P10: Jenis Zon Lokasi | Q10: Type de zone de l’emplacement | R10: 위치 구역 유형 | S10: 位置區域類型 | T10: Placeringszonetyper | U10: Sijaintivyöhyketyypit | V10: Helyzónatípusok | W10: Typer plasseringssone | X10: Typy zón polohy
A11: **Date | B11: Date | C11: Fecha | D11: Datum | E11: データ | F11: Data | G11: Data | H11: Datum | I11: Data | J11: 日期 | K11: วันที่ | L11: Tanggal | M11: Datum | N11: Datum | O11: Tarih | P11: Tarikh | Q11: Date | R11: 날짜 | S11: 日期 | T11: Dato | U11: Päivämäärä | V11: Dátum | W11: Dato | X11: Dátum
A12: **Start Time | B12: Heure de départ | C12: Hora de inicio | D12: Startzeit | E12: 開始時間 | F12: Godzina rozpoczecia | G12: Hora de início | H12: Starttijd | I12: Ora iniziale | J12: 开始时间 | K12: เวลาเริ่มต้น | L12: Waktu Mulai | M12: Čas začátku | N12: Starttid | O12: Başlangıç Saati | P12: Masa Mula | Q12: Heure de début | R12: 시작 시간 | S12: 開始時間 | T12: Starttidspunkt | U12: Alkamisaika | V12: Kezdés ideje | W12: Starttidspunkt | X12: Čas začiatku
... A25: **Days | B25: Jours | C25: Días | D25: Tage | E25: 日 | F25: Dni | G25: Dias | H25: Dagen | I25: Giorni | J25: 天数 | K25: วัน | L25: Hari | M25: Dny | N25: Dagar | O25: Gün | P25: Hari | Q25: Jours | R25: 일 | S25: 天 | T25: Dage | U25: Päivät | V25: Napok | W25: Dager | X25: Dni
